<sdf version='1.7'>
  <world name='default'>
    <plugin name='gazebo_ros_state' filename='libgazebo_ros_state.so'>
      <ros>
        <namespace>/gazebo</namespace>
      </ros>
      <update_rate>1000</update_rate>
    </plugin>
    <light name='sun' type='directional'>
      <cast_shadows>1</cast_shadows>
      <pose>0 0 10 0 -0 0</pose>
      <diffuse>1 1 1 1</diffuse>
      <specular>1 1 1 1</specular>
      <attenuation>
        <range>1000</range>
        <constant>0.9</constant>
        <linear>0.01</linear>
        <quadratic>0.001</quadratic>
      </attenuation>
      <direction>-0.5 0.1 -0.9</direction>
      <spot>
        <inner_angle>0</inner_angle>
        <outer_angle>0</outer_angle>
        <falloff>0</falloff>
      </spot>
    </light>
    <model name='ground_plane'>
      <static>1</static>
      <link name='link'>
        <collision name='collision'>
          <geometry>
            <plane>
              <normal>0 0 1</normal>
              <size>100 100</size>
            </plane>
          </geometry>
          <surface>
            <contact>
              <collide_bitmask>65535</collide_bitmask>
              <ode/>
            </contact>
            <friction>
              <ode>
                <mu>100</mu>
                <mu2>50</mu2>
              </ode>
              <torsional>
                <ode/>
              </torsional>
            </friction>
            <bounce/>
          </surface>
          <max_contacts>10</max_contacts>
        </collision>
        <visual name='visual'>
          <cast_shadows>0</cast_shadows>
          <geometry>
            <plane>
              <normal>0 0 1</normal>
              <size>100 100</size>
            </plane>
          </geometry>
          <material>
            <script>
              <uri>file://media/materials/scripts/gazebo.material</uri>
              <name>Gazebo/Grey</name>
            </script>
          </material>
        </visual>
        <self_collide>0</self_collide>
        <enable_wind>0</enable_wind>
        <kinematic>0</kinematic>
      </link>
    </model>
    <gravity>0 0 -9.8</gravity>
    <magnetic_field>6e-06 2.3e-05 -4.2e-05</magnetic_field>
    <atmosphere type='adiabatic'/>
    <physics type='ode'>
      <max_step_size>0.001</max_step_size>
      <real_time_factor>1</real_time_factor>
      <real_time_update_rate>1000</real_time_update_rate>
    </physics>
    <scene>
      <ambient>0.4 0.4 0.4 1</ambient>
      <background>0.7 0.7 0.7 1</background>
      <shadows>1</shadows>
    </scene>
    <audio>
      <device>default</device>
    </audio>
    <wind/>
    <spherical_coordinates>
      <surface_model>EARTH_WGS84</surface_model>
      <latitude_deg>0</latitude_deg>
      <longitude_deg>0</longitude_deg>
      <elevation>0</elevation>
      <heading_deg>0</heading_deg>
    </spherical_coordinates>
    <model name='rhex'>
      <link name='base_link'>
        <inertial>
          <pose>0.000443 8e-06 0.00189 0 -0 0</pose>
          <mass>12.646</mass>
          <inertia>
            <ixx>0.0587881</ixx>
            <ixy>-2.79884e-05</ixy>
            <ixz>-0.000629803</ixz>
            <iyy>0.338307</iyy>
            <iyz>-1.20641e-05</iyz>
            <izz>0.36304</izz>
          </inertia>
        </inertial>
        <collision name='base_link_collision'>
          <pose>0 0 0 0 -0 0</pose>
          <geometry>
            <mesh>
              <scale>1 1 1</scale>
              <uri>file:///home/rhex/mnt/rhex_ws/install/rhex_description/share/rhex_description/meshes/rpk10_chassis.dae</uri>
            </mesh>
          </geometry>
          <surface>
            <contact>
              <ode/>
            </contact>
            <friction>
              <ode/>
              <torsional>
                <ode/>
              </torsional>
            </friction>
            <bounce/>
          </surface>
          <max_contacts>10</max_contacts>
        </collision>
        <collision name='base_link_fixed_joint_lump__upper_case_link_collision_1'>
          <pose>0 0 0.055 0 -0 0</pose>
          <geometry>
            <mesh>
              <scale>0.001 0.001 0.001</scale>
              <uri>file:///home/rhex/mnt/rhex_ws/install/rhex_description/share/rhex_description/meshes/upper_case.dae</uri>
            </mesh>
          </geometry>
          <max_contacts>10</max_contacts>
          <surface>
            <contact>
              <ode/>
            </contact>
            <bounce/>
            <friction>
              <torsional>
                <ode/>
              </torsional>
              <ode/>
            </friction>
          </surface>
        </collision>
        <collision name='base_link_fixed_joint_lump__camera_link_collision_2'>
          <pose>0.267 0.0055 0.1155 0 -0 0</pose>
          <geometry>
            <box>
              <size>0.015 0.0867 0.022</size>
            </box>
          </geometry>
          <surface>
            <contact>
              <ode/>
            </contact>
            <friction>
              <ode/>
              <torsional>
                <ode/>
              </torsional>
            </friction>
            <bounce/>
          </surface>
          <max_contacts>10</max_contacts>
        </collision>
        <collision name='base_link_fixed_joint_lump__imu_link_collision_3'>
          <pose>0.267 -0.005 0.0885 0 -0 0</pose>
          <geometry>
            <box>
              <size>0.015 0.115 0.02</size>
            </box>
          </geometry>
          <surface>
            <contact>
              <ode/>
            </contact>
            <friction>
              <ode/>
              <torsional>
                <ode/>
              </torsional>
            </friction>
            <bounce/>
          </surface>
          <max_contacts>10</max_contacts>
        </collision>
        <collision name='base_link_fixed_joint_lump__lidar_link_collision_4'>
          <pose>0 0 0.172 0 -0 0</pose>
          <geometry>
            <cylinder>
              <length>0.056</length>
              <radius>0.0508</radius>
            </cylinder>
          </geometry>
          <surface>
            <contact>
              <ode/>
            </contact>
            <friction>
              <ode/>
              <torsional>
                <ode/>
              </torsional>
            </friction>
            <bounce/>
          </surface>
          <max_contacts>10</max_contacts>
        </collision>
        <visual name='base_link_visual'>
          <pose>0 0 0 0 -0 0</pose>
          <geometry>
            <mesh>
              <scale>1 1 1</scale>
              <uri>file:///home/rhex/mnt/rhex_ws/install/rhex_description/share/rhex_description/meshes/rpk10_chassis.dae</uri>
            </mesh>
          </geometry>
          <material>
            <script>
              <name>Gazebo/Red</name>
              <uri>file://media/materials/scripts/gazebo.material</uri>
            </script>
          </material>
        </visual>
        <visual name='base_link_fixed_joint_lump__upper_case_link_visual_1'>
          <pose>0 0 0.055 0 -0 0</pose>
          <geometry>
            <mesh>
              <scale>0.001 0.001 0.001</scale>
              <uri>file:///home/rhex/mnt/rhex_ws/install/rhex_description/share/rhex_description/meshes/upper_case.dae</uri>
            </mesh>
          </geometry>
        </visual>
        <visual name='base_link_fixed_joint_lump__camera_link_visual_2'>
          <pose>0.267 0.0055 0.1155 0 -0 0</pose>
          <geometry>
            <box>
              <size>0.015 0.0867 0.022</size>
            </box>
          </geometry>
        </visual>
        <visual name='base_link_fixed_joint_lump__imu_link_visual_3'>
          <pose>0.267 -0.005 0.0885 0 -0 0</pose>
          <geometry>
            <box>
              <size>0.015 0.115 0.02</size>
            </box>
          </geometry>
        </visual>
        <visual name='base_link_fixed_joint_lump__lidar_link_visual_4'>
          <pose>0 0 0.172 0 -0 0</pose>
          <geometry>
            <cylinder>
              <length>0.056</length>
              <radius>0.0508</radius>
            </cylinder>
          </geometry>
        </visual>
        <sensor name='depth_camera' type='depth'>
          <visualize>1</visualize>
          <update_rate>30</update_rate>
          <camera name='camera'>
            <horizontal_fov>1.0472</horizontal_fov>
            <image>
              <width>640</width>
              <height>480</height>
              <format>B8G8R8</format>
            </image>
            <clip>
              <near>0.05</near>
              <far>30</far>
            </clip>
            <noise>
              <type>gaussian</type>
              <mean>0</mean>
              <stddev>0.007</stddev>
            </noise>
          </camera>
          <plugin name='depth_camera_controller' filename='libgazebo_ros_camera.so'>
            <update_rate>0.0</update_rate>
            <frame_name>camera_depth_frame</frame_name>
            <min_depth>0.2</min_depth>
            <max_depth>4.0</max_depth>
          </plugin>
          <pose>0.267 0.0055 0.1155 0 -0 0</pose>
        </sensor>
        <sensor name='imu_sensor' type='imu'>
          <plugin name='imu_plugin' filename='libgazebo_ros_imu_sensor.so'>
            <ros>
              <namespace>/imu</namespace>
              <remapping>~/out:=data</remapping>
            </ros>
            <initial_orientation_as_reference>0</initial_orientation_as_reference>
          </plugin>
          <always_on>1</always_on>
          <update_rate>1000</update_rate>
          <visualize>1</visualize>
          <imu>
            <angular_velocity>
              <x>
                <noise type='gaussian'>
                  <mean>0</mean>
                  <stddev>0.0002</stddev>
                  <bias_mean>7.5e-06</bias_mean>
                  <bias_stddev>8e-07</bias_stddev>
                </noise>
              </x>
              <y>
                <noise type='gaussian'>
                  <mean>0</mean>
                  <stddev>0.0002</stddev>
                  <bias_mean>7.5e-06</bias_mean>
                  <bias_stddev>8e-07</bias_stddev>
                </noise>
              </y>
              <z>
                <noise type='gaussian'>
                  <mean>0</mean>
                  <stddev>0.0002</stddev>
                  <bias_mean>7.5e-06</bias_mean>
                  <bias_stddev>8e-07</bias_stddev>
                </noise>
              </z>
            </angular_velocity>
            <linear_acceleration>
              <x>
                <noise type='gaussian'>
                  <mean>0</mean>
                  <stddev>0.017</stddev>
                  <bias_mean>0.1</bias_mean>
                  <bias_stddev>0.001</bias_stddev>
                </noise>
              </x>
              <y>
                <noise type='gaussian'>
                  <mean>0</mean>
                  <stddev>0.017</stddev>
                  <bias_mean>0.1</bias_mean>
                  <bias_stddev>0.001</bias_stddev>
                </noise>
              </y>
              <z>
                <noise type='gaussian'>
                  <mean>0</mean>
                  <stddev>0.017</stddev>
                  <bias_mean>0.1</bias_mean>
                  <bias_stddev>0.001</bias_stddev>
                </noise>
              </z>
            </linear_acceleration>
          </imu>
          <pose>0.267 -0.005 0.0885 0 -0 0</pose>
        </sensor>
        <sensor name='lidar' type='ray'>
          <always_on>1</always_on>
          <visualize>0</visualize>
          <update_rate>5</update_rate>
          <ray>
            <scan>
              <horizontal>
                <samples>360</samples>
                <resolution>1</resolution>
                <min_angle>0</min_angle>
                <max_angle>6.28</max_angle>
              </horizontal>
              <vertical>
                <samples>1</samples>
                <min_angle>0</min_angle>
                <max_angle>0</max_angle>
              </vertical>
            </scan>
            <range>
              <min>0.12</min>
              <max>3.5</max>
              <resolution>0.015</resolution>
            </range>
            <noise>
              <type>gaussian</type>
              <mean>0</mean>
              <stddev>0.01</stddev>
            </noise>
          </ray>
          <plugin name='scan' filename='libgazebo_ros_ray_sensor.so'>
            <ros>
              <remapping>~/out:=scan</remapping>
            </ros>
            <output_type>sensor_msgs/LaserScan</output_type>
            <frame_name>lidar_link</frame_name>
          </plugin>
          <pose>0 0 0.172 0 -0 0</pose>
        </sensor>
        <self_collide>0</self_collide>
        <enable_wind>0</enable_wind>
        <kinematic>0</kinematic>
      </link>
      <joint name='front_left_joint' type='revolute'>
        <pose relative_to='base_link'>0.19 0.1235 0 0 -0 0</pose>
        <parent>base_link</parent>
        <child>front_left_link</child>
        <axis>
          <xyz>0 1 0</xyz>
          <limit>
            <lower>-1e+16</lower>
            <upper>1e+16</upper>
          </limit>
          <dynamics>
            <damping>0.5</damping>
            <friction>0</friction>
            <spring_reference>0</spring_reference>
            <spring_stiffness>0</spring_stiffness>
          </dynamics>
        </axis>
      </joint>
      <link name='front_left_link'>
        <pose relative_to='front_left_joint'>0 0 0 0 -0 0</pose>
        <inertial>
          <pose>0 0 -0.08 0 -0 0</pose>
          <mass>0.05</mass>
          <inertia>
            <ixx>0.000130865</ixx>
            <ixy>0</ixy>
            <ixz>0</ixz>
            <iyy>0.000166666</iyy>
            <iyz>0</iyz>
            <izz>4.40694e-05</izz>
          </inertia>
        </inertial>
        <collision name='front_left_link_collision'>
          <pose>0 0 0 0 -0 0</pose>
          <geometry>
            <mesh>
              <scale>1 1 1</scale>
              <uri>file:///home/rhex/mnt/rhex_ws/install/rhex_description/share/rhex_description/meshes/rpk10_leg.dae</uri>
            </mesh>
          </geometry>
          <surface>
            <contact>
              <ode>
                <kp>1e+12</kp>
                <kd>100</kd>
                <min_depth>0.05</min_depth>
              </ode>
            </contact>
            <friction>
              <ode>
                <mu>50</mu>
                <mu2>50</mu2>
              </ode>
              <torsional>
                <ode/>
              </torsional>
            </friction>
            <bounce/>
          </surface>
          <max_contacts>10</max_contacts>
        </collision>
        <visual name='front_left_link_visual'>
          <pose>0 0 0 0 -0 0</pose>
          <geometry>
            <mesh>
              <scale>1 1 1</scale>
              <uri>file:///home/rhex/mnt/rhex_ws/install/rhex_description/share/rhex_description/meshes/rpk10_leg.dae</uri>
            </mesh>
          </geometry>
        </visual>
        <self_collide>0</self_collide>
        <enable_wind>0</enable_wind>
        <kinematic>0</kinematic>
      </link>
      <joint name='front_right_joint' type='revolute'>
        <pose relative_to='base_link'>0.19 -0.1235 0 0 -0 0</pose>
        <parent>base_link</parent>
        <child>front_right_link</child>
        <axis>
          <xyz>0 1 0</xyz>
          <limit>
            <lower>-1e+16</lower>
            <upper>1e+16</upper>
          </limit>
          <dynamics>
            <damping>0.5</damping>
            <friction>0</friction>
            <spring_reference>0</spring_reference>
            <spring_stiffness>0</spring_stiffness>
          </dynamics>
        </axis>
      </joint>
      <link name='front_right_link'>
        <pose relative_to='front_right_joint'>0 0 0 0 -0 0</pose>
        <inertial>
          <pose>0 0 -0.08 0 -0 0</pose>
          <mass>0.05</mass>
          <inertia>
            <ixx>0.000130865</ixx>
            <ixy>0</ixy>
            <ixz>0</ixz>
            <iyy>0.000166666</iyy>
            <iyz>0</iyz>
            <izz>4.40694e-05</izz>
          </inertia>
        </inertial>
        <collision name='front_right_link_collision'>
          <pose>0 0 0 0 -0 0</pose>
          <geometry>
            <mesh>
              <scale>1 1 1</scale>
              <uri>file:///home/rhex/mnt/rhex_ws/install/rhex_description/share/rhex_description/meshes/rpk10_leg.dae</uri>
            </mesh>
          </geometry>
          <surface>
            <contact>
              <ode>
                <kp>1e+12</kp>
                <kd>100</kd>
                <min_depth>0.05</min_depth>
              </ode>
            </contact>
            <friction>
              <ode>
                <mu>50</mu>
                <mu2>50</mu2>
              </ode>
              <torsional>
                <ode/>
              </torsional>
            </friction>
            <bounce/>
          </surface>
          <max_contacts>10</max_contacts>
        </collision>
        <visual name='front_right_link_visual'>
          <pose>0 0 0 0 -0 0</pose>
          <geometry>
            <mesh>
              <scale>1 1 1</scale>
              <uri>file:///home/rhex/mnt/rhex_ws/install/rhex_description/share/rhex_description/meshes/rpk10_leg.dae</uri>
            </mesh>
          </geometry>
        </visual>
        <self_collide>0</self_collide>
        <enable_wind>0</enable_wind>
        <kinematic>0</kinematic>
      </link>
      <joint name='mid_left_joint' type='revolute'>
        <pose relative_to='base_link'>0 0.162 0 0 -0 0</pose>
        <parent>base_link</parent>
        <child>mid_left_link</child>
        <axis>
          <xyz>0 1 0</xyz>
          <limit>
            <lower>-1e+16</lower>
            <upper>1e+16</upper>
          </limit>
          <dynamics>
            <damping>0.5</damping>
            <friction>0</friction>
            <spring_reference>0</spring_reference>
            <spring_stiffness>0</spring_stiffness>
          </dynamics>
        </axis>
      </joint>
      <link name='mid_left_link'>
        <pose relative_to='mid_left_joint'>0 0 0 0 -0 0</pose>
        <inertial>
          <pose>0 0 -0.08 0 -0 0</pose>
          <mass>0.05</mass>
          <inertia>
            <ixx>0.000130865</ixx>
            <ixy>0</ixy>
            <ixz>0</ixz>
            <iyy>0.000166666</iyy>
            <iyz>0</iyz>
            <izz>4.40694e-05</izz>
          </inertia>
        </inertial>
        <collision name='mid_left_link_collision'>
          <pose>0 0 0 0 -0 0</pose>
          <geometry>
            <mesh>
              <scale>1 1 1</scale>
              <uri>file:///home/rhex/mnt/rhex_ws/install/rhex_description/share/rhex_description/meshes/rpk10_leg.dae</uri>
            </mesh>
          </geometry>
          <surface>
            <contact>
              <ode>
                <kp>1e+12</kp>
                <kd>100</kd>
                <min_depth>0.05</min_depth>
              </ode>
            </contact>
            <friction>
              <ode>
                <mu>50</mu>
                <mu2>50</mu2>
              </ode>
              <torsional>
                <ode/>
              </torsional>
            </friction>
            <bounce/>
          </surface>
          <max_contacts>10</max_contacts>
        </collision>
        <visual name='mid_left_link_visual'>
          <pose>0 0 0 0 -0 0</pose>
          <geometry>
            <mesh>
              <scale>1 1 1</scale>
              <uri>file:///home/rhex/mnt/rhex_ws/install/rhex_description/share/rhex_description/meshes/rpk10_leg.dae</uri>
            </mesh>
          </geometry>
        </visual>
        <self_collide>0</self_collide>
        <enable_wind>0</enable_wind>
        <kinematic>0</kinematic>
      </link>
      <joint name='mid_right_joint' type='revolute'>
        <pose relative_to='base_link'>0 -0.162 0 0 -0 0</pose>
        <parent>base_link</parent>
        <child>mid_right_link</child>
        <axis>
          <xyz>0 1 0</xyz>
          <limit>
            <lower>-1e+16</lower>
            <upper>1e+16</upper>
          </limit>
          <dynamics>
            <damping>0.5</damping>
            <friction>0</friction>
            <spring_reference>0</spring_reference>
            <spring_stiffness>0</spring_stiffness>
          </dynamics>
        </axis>
      </joint>
      <link name='mid_right_link'>
        <pose relative_to='mid_right_joint'>0 0 0 0 -0 0</pose>
        <inertial>
          <pose>0 0 -0.08 0 -0 0</pose>
          <mass>0.05</mass>
          <inertia>
            <ixx>0.000130865</ixx>
            <ixy>0</ixy>
            <ixz>0</ixz>
            <iyy>0.000166666</iyy>
            <iyz>0</iyz>
            <izz>4.40694e-05</izz>
          </inertia>
        </inertial>
        <collision name='mid_right_link_collision'>
          <pose>0 0 0 0 -0 0</pose>
          <geometry>
            <mesh>
              <scale>1 1 1</scale>
              <uri>file:///home/rhex/mnt/rhex_ws/install/rhex_description/share/rhex_description/meshes/rpk10_leg.dae</uri>
            </mesh>
          </geometry>
          <surface>
            <contact>
              <ode>
                <kp>1e+12</kp>
                <kd>100</kd>
                <min_depth>0.05</min_depth>
              </ode>
            </contact>
            <friction>
              <ode>
                <mu>50</mu>
                <mu2>50</mu2>
              </ode>
              <torsional>
                <ode/>
              </torsional>
            </friction>
            <bounce/>
          </surface>
          <max_contacts>10</max_contacts>
        </collision>
        <visual name='mid_right_link_visual'>
          <pose>0 0 0 0 -0 0</pose>
          <geometry>
            <mesh>
              <scale>1 1 1</scale>
              <uri>file:///home/rhex/mnt/rhex_ws/install/rhex_description/share/rhex_description/meshes/rpk10_leg.dae</uri>
            </mesh>
          </geometry>
        </visual>
        <self_collide>0</self_collide>
        <enable_wind>0</enable_wind>
        <kinematic>0</kinematic>
      </link>
      <joint name='rear_left_joint' type='revolute'>
        <pose relative_to='base_link'>-0.19 0.1235 0 0 -0 0</pose>
        <parent>base_link</parent>
        <child>rear_left_link</child>
        <axis>
          <xyz>0 1 0</xyz>
          <limit>
            <lower>-1e+16</lower>
            <upper>1e+16</upper>
          </limit>
          <dynamics>
            <damping>0.5</damping>
            <friction>0</friction>
            <spring_reference>0</spring_reference>
            <spring_stiffness>0</spring_stiffness>
          </dynamics>
        </axis>
      </joint>
      <link name='rear_left_link'>
        <pose relative_to='rear_left_joint'>0 0 0 0 -0 0</pose>
        <inertial>
          <pose>0 0 -0.08 0 -0 0</pose>
          <mass>0.05</mass>
          <inertia>
            <ixx>0.000130865</ixx>
            <ixy>0</ixy>
            <ixz>0</ixz>
            <iyy>0.000166666</iyy>
            <iyz>0</iyz>
            <izz>4.40694e-05</izz>
          </inertia>
        </inertial>
        <collision name='rear_left_link_collision'>
          <pose>0 0 0 0 -0 0</pose>
          <geometry>
            <mesh>
              <scale>1 1 1</scale>
              <uri>file:///home/rhex/mnt/rhex_ws/install/rhex_description/share/rhex_description/meshes/rpk10_leg.dae</uri>
            </mesh>
          </geometry>
          <surface>
            <contact>
              <ode>
                <kp>1e+12</kp>
                <kd>100</kd>
                <min_depth>0.05</min_depth>
              </ode>
            </contact>
            <friction>
              <ode>
                <mu>50</mu>
                <mu2>50</mu2>
              </ode>
              <torsional>
                <ode/>
              </torsional>
            </friction>
            <bounce/>
          </surface>
          <max_contacts>10</max_contacts>
        </collision>
        <visual name='rear_left_link_visual'>
          <pose>0 0 0 0 -0 0</pose>
          <geometry>
            <mesh>
              <scale>1 1 1</scale>
              <uri>file:///home/rhex/mnt/rhex_ws/install/rhex_description/share/rhex_description/meshes/rpk10_leg.dae</uri>
            </mesh>
          </geometry>
        </visual>
        <self_collide>0</self_collide>
        <enable_wind>0</enable_wind>
        <kinematic>0</kinematic>
      </link>
      <joint name='rear_right_joint' type='revolute'>
        <pose relative_to='base_link'>-0.19 -0.1235 0 0 -0 0</pose>
        <parent>base_link</parent>
        <child>rear_right_link</child>
        <axis>
          <xyz>0 1 0</xyz>
          <limit>
            <lower>-1e+16</lower>
            <upper>1e+16</upper>
          </limit>
          <dynamics>
            <damping>0.5</damping>
            <friction>0</friction>
            <spring_reference>0</spring_reference>
            <spring_stiffness>0</spring_stiffness>
          </dynamics>
        </axis>
      </joint>
      <link name='rear_right_link'>
        <pose relative_to='rear_right_joint'>0 0 0 0 -0 0</pose>
        <inertial>
          <pose>0 0 -0.08 0 -0 0</pose>
          <mass>0.05</mass>
          <inertia>
            <ixx>0.000130865</ixx>
            <ixy>0</ixy>
            <ixz>0</ixz>
            <iyy>0.000166666</iyy>
            <iyz>0</iyz>
            <izz>4.40694e-05</izz>
          </inertia>
        </inertial>
        <collision name='rear_right_link_collision'>
          <pose>0 0 0 0 -0 0</pose>
          <geometry>
            <mesh>
              <scale>1 1 1</scale>
              <uri>file:///home/rhex/mnt/rhex_ws/install/rhex_description/share/rhex_description/meshes/rpk10_leg.dae</uri>
            </mesh>
          </geometry>
          <surface>
            <contact>
              <ode>
                <kp>1e+12</kp>
                <kd>100</kd>
                <min_depth>0.05</min_depth>
              </ode>
            </contact>
            <friction>
              <ode>
                <mu>50</mu>
                <mu2>50</mu2>
              </ode>
              <torsional>
                <ode/>
              </torsional>
            </friction>
            <bounce/>
          </surface>
          <max_contacts>10</max_contacts>
        </collision>
        <visual name='rear_right_link_visual'>
          <pose>0 0 0 0 -0 0</pose>
          <geometry>
            <mesh>
              <scale>1 1 1</scale>
              <uri>file:///home/rhex/mnt/rhex_ws/install/rhex_description/share/rhex_description/meshes/rpk10_leg.dae</uri>
            </mesh>
          </geometry>
        </visual>
        <self_collide>0</self_collide>
        <enable_wind>0</enable_wind>
        <kinematic>0</kinematic>
      </link>
      <plugin name='p3d_base_controller' filename='libgazebo_ros_p3d.so'>
        <ros>
          <argument>/odom:=odom/robot_pos</argument>
        </ros>
        <body_name>base_link</body_name>
        <frame_name>world</frame_name>
        <update_rate>30.0</update_rate>
        <xyz_offset>0 0 0</xyz_offset>
        <rpy_offset>0 0 0</rpy_offset>
        <gaussian_noise>0.01</gaussian_noise>
      </plugin>
      <static>0</static>
      <plugin name='gazebo_ros2_control' filename='libgazebo_ros2_control.so'>
        <parameters>/home/rhex/mnt/rhex_ws/install/rhex_description/share/rhex_description/config/ros_control.yaml</parameters>
      </plugin>
      <pose>0 0 0.1 0 -0 0</pose>
    </model>
    <model name='person_walking'>
      <link name='link'>
        <inertial>
          <pose>0 0 0.95 0 -0 0</pose>
          <mass>80</mass>
          <inertia>
            <ixx>27.82</ixx>
            <ixy>0</ixy>
            <ixz>0</ixz>
            <iyy>24.88</iyy>
            <iyz>0</iyz>
            <izz>4.57</izz>
          </inertia>
        </inertial>
        <collision name='bottom'>
          <pose>0 0 0.01 0 -0 0</pose>
          <geometry>
            <box>
              <size>0.35 0.75 0.02</size>
            </box>
          </geometry>
          <max_contacts>10</max_contacts>
          <surface>
            <contact>
              <ode/>
            </contact>
            <bounce/>
            <friction>
              <torsional>
                <ode/>
              </torsional>
              <ode/>
            </friction>
          </surface>
        </collision>
        <collision name='person'>
          <pose>0 0 -0.02 0 -0 0</pose>
          <geometry>
            <mesh>
              <uri>model://person_walking/meshes/walking.dae</uri>
            </mesh>
          </geometry>
          <max_contacts>10</max_contacts>
          <surface>
            <contact>
              <ode/>
            </contact>
            <bounce/>
            <friction>
              <torsional>
                <ode/>
              </torsional>
              <ode/>
            </friction>
          </surface>
        </collision>
        <visual name='visual'>
          <pose>0 0 -0.02 0 -0 0</pose>
          <geometry>
            <mesh>
              <uri>model://person_walking/meshes/walking.dae</uri>
            </mesh>
          </geometry>
        </visual>
        <self_collide>0</self_collide>
        <enable_wind>0</enable_wind>
        <kinematic>0</kinematic>
      </link>
      <pose>0.333602 10.6632 0 0 -0 0</pose>
    </model>
    <model name='person_standing'>
      <link name='link'>
        <inertial>
          <pose>0 -0.1 0.95 0 -0 0</pose>
          <mass>80</mass>
          <inertia>
            <ixx>24.88</ixx>
            <ixy>0</ixy>
            <ixz>0</ixz>
            <iyy>25.73</iyy>
            <iyz>0</iyz>
            <izz>2.48</izz>
          </inertia>
        </inertial>
        <collision name='bottom'>
          <pose>0 -0.1 0.01 0 -0 0</pose>
          <geometry>
            <box>
              <size>0.5 0.35 0.02</size>
            </box>
          </geometry>
          <max_contacts>10</max_contacts>
          <surface>
            <contact>
              <ode/>
            </contact>
            <bounce/>
            <friction>
              <torsional>
                <ode/>
              </torsional>
              <ode/>
            </friction>
          </surface>
        </collision>
        <collision name='person'>
          <pose>0 0 0.02 0.04 -0 0</pose>
          <geometry>
            <mesh>
              <uri>model://person_standing/meshes/standing.dae</uri>
            </mesh>
          </geometry>
          <max_contacts>10</max_contacts>
          <surface>
            <contact>
              <ode/>
            </contact>
            <bounce/>
            <friction>
              <torsional>
                <ode/>
              </torsional>
              <ode/>
            </friction>
          </surface>
        </collision>
        <visual name='visual'>
          <pose>0 0 0.02 0.04 -0 0</pose>
          <geometry>
            <mesh>
              <uri>model://person_standing/meshes/standing.dae</uri>
            </mesh>
          </geometry>
        </visual>
        <self_collide>0</self_collide>
        <enable_wind>0</enable_wind>
        <kinematic>0</kinematic>
      </link>
      <pose>-3.24211 0.008518 0 0 -0 0</pose>
    </model>
    <model name='person_standing_0'>
      <link name='link'>
        <inertial>
          <pose>0 -0.1 0.95 0 -0 0</pose>
          <mass>80</mass>
          <inertia>
            <ixx>24.88</ixx>
            <ixy>0</ixy>
            <ixz>0</ixz>
            <iyy>25.73</iyy>
            <iyz>0</iyz>
            <izz>2.48</izz>
          </inertia>
        </inertial>
        <collision name='bottom'>
          <pose>0 -0.1 0.01 0 -0 0</pose>
          <geometry>
            <box>
              <size>0.5 0.35 0.02</size>
            </box>
          </geometry>
          <max_contacts>10</max_contacts>
          <surface>
            <contact>
              <ode/>
            </contact>
            <bounce/>
            <friction>
              <torsional>
                <ode/>
              </torsional>
              <ode/>
            </friction>
          </surface>
        </collision>
        <collision name='person'>
          <pose>0 0 0.02 0.04 -0 0</pose>
          <geometry>
            <mesh>
              <uri>model://person_standing/meshes/standing.dae</uri>
            </mesh>
          </geometry>
          <max_contacts>10</max_contacts>
          <surface>
            <contact>
              <ode/>
            </contact>
            <bounce/>
            <friction>
              <torsional>
                <ode/>
              </torsional>
              <ode/>
            </friction>
          </surface>
        </collision>
        <visual name='visual'>
          <pose>0 0 0.02 0.04 -0 0</pose>
          <geometry>
            <mesh>
              <uri>model://person_standing/meshes/standing.dae</uri>
            </mesh>
          </geometry>
        </visual>
        <self_collide>0</self_collide>
        <enable_wind>0</enable_wind>
        <kinematic>0</kinematic>
      </link>
      <pose>-7.03934 2.00428 0 0 -0 0</pose>
    </model>
    <state world_name='default'>
      <sim_time>342 425000000</sim_time>
      <real_time>291 209372496</real_time>
      <wall_time>1720521759 77125589</wall_time>
      <iterations>288473</iterations>
      <model name='ground_plane'>
        <pose>0 0 0 0 -0 0</pose>
        <scale>1 1 1</scale>
        <link name='link'>
          <pose>0 0 0 0 -0 0</pose>
          <velocity>0 0 0 0 -0 0</velocity>
          <acceleration>0 0 0 0 -0 0</acceleration>
          <wrench>0 0 0 0 -0 0</wrench>
        </link>
      </model>
      <model name='person_standing'>
        <pose>8.68898 3.19622 0 0 1e-06 -1.50456</pose>
        <scale>1 1 1</scale>
        <link name='link'>
          <pose>8.68898 3.19622 0 0 1e-06 -1.50456</pose>
          <velocity>0 0 0 0 -0 0</velocity>
          <acceleration>-0.931712 2.09809 1.29069 -2.11355 -1.11697 -0.113395</acceleration>
          <wrench>-74.5369 167.847 103.255 0 -0 0</wrench>
        </link>
      </model>
      <model name='person_walking'>
        <pose>8.29359 -1.4313 -1e-06 -2e-06 1e-06 0.000585</pose>
        <scale>1 1 1</scale>
        <link name='link'>
          <pose>8.29359 -1.4313 -1e-06 -2e-06 1e-06 0.000585</pose>
          <velocity>0 0 0 0 -0 0</velocity>
          <acceleration>0.967613 2.04194 -2.65401 -2.12992 1.06057 0.106137</acceleration>
          <wrench>77.4091 163.355 -212.32 0 -0 0</wrench>
        </link>
      </model>
      <model name='rhex'>
        <pose>-0.026088 0.004662 0.056011 0 4e-06 0.007542</pose>
        <scale>1 1 1</scale>
        <link name='base_link'>
          <pose>-0.026088 0.004662 0.056011 0 4e-06 0.007542</pose>
          <velocity>0.000209 4.6e-05 -0.000588 -0.000141 0.0037 0.000229</velocity>
          <acceleration>1.47703 0.068194 -4.04728 0.398809 0.35255 0.231091</acceleration>
          <wrench>18.6785 0.862387 -51.1819 0 -0 0</wrench>
        </link>
        <link name='front_left_link'>
          <pose>0.162968 0.129589 0.056022 -3.14155 -1.27996 -3.13407</pose>
          <velocity>-0.00035 0.000431 -0.000248 -0.003387 -0.006404 -0.003213</velocity>
          <acceleration>1.22459 0.292392 -9.04174 -1.42121 0.390308 -0.070298</acceleration>
          <wrench>0.06123 0.01462 -0.452087 0 -0 0</wrench>
        </link>
        <link name='front_right_link'>
          <pose>0.164832 -0.117404 0.056019 -3.14152 -1.27979 -3.13409</pose>
          <velocity>-0.000318 -9.2e-05 -0.000483 -0.001144 -0.007376 0.002623</velocity>
          <acceleration>1.23151 0.165009 -9.14923 -0.360434 1.32033 -2.86156</acceleration>
          <wrench>0.061576 0.00825 -0.457462 0 -0 0</wrench>
        </link>
        <link name='mid_left_link'>
          <pose>-0.027318 0.166657 0.056023 3.14159 -1.27994 -3.13405</pose>
          <velocity>-0.000215 0.000153 -0.000122 -0.00111 -0.003925 -0.001215</velocity>
          <acceleration>1.41489 0.115027 -4.97365 2.24142 -1.01423 -1.18559</acceleration>
          <wrench>0.070745 0.005751 -0.248682 0 -0 0</wrench>
        </link>
        <link name='mid_right_link'>
          <pose>-0.024871 -0.157333 0.056019 -3.14159 -1.27991 -3.13406</pose>
          <velocity>-0.000103 -5.5e-05 3.7e-05 -0.001179 -0.00178 0.001605</velocity>
          <acceleration>1.57519 0.125027 -4.91043 2.60485 1.13377 -0.108327</acceleration>
          <wrench>0.07876 0.006251 -0.245521 0 -0 0</wrench>
        </link>
        <link name='rear_left_link'>
          <pose>-0.217023 0.126725 0.056025 3.14151 -1.27996 -3.13396</pose>
          <velocity>0.000217 0.000177 0.000601 -0.004346 0.003886 0.000881</velocity>
          <acceleration>2.025 0.3741 -0.703431 -0.025513 0.467543 -2.07563</acceleration>
          <wrench>0.10125 0.018705 -0.035172 0 -0 0</wrench>
        </link>
        <link name='rear_right_link'>
          <pose>-0.215154 -0.120267 0.056017 -3.14159 -1.27983 -3.13406</pose>
          <velocity>0.000187 -1.7e-05 0.000352 -0.001389 0.003254 0.001261</velocity>
          <acceleration>1.98098 0.1415 -0.850665 2.04818 -0.118313 -0.331011</acceleration>
          <wrench>0.099049 0.007075 -0.042533 0 -0 0</wrench>
        </link>
      </model>
      <light name='sun'>
        <pose>0 0 10 0 -0 0</pose>
      </light>
    </state>
    <gui fullscreen='0'>
      <camera name='user_camera'>
        <pose>5.15979 -9.44993 4.40417 0 0.359643 1.5962</pose>
        <view_controller>orbit</view_controller>
        <projection_type>perspective</projection_type>
      </camera>
    </gui>
    <model name='rhex'>
      <link name='base_link'>
        <inertial>
          <pose>0.000443 8e-06 0.00189 0 -0 0</pose>
          <mass>12.646</mass>
          <inertia>
            <ixx>0.0587881</ixx>
            <ixy>-2.79884e-05</ixy>
            <ixz>-0.000629803</ixz>
            <iyy>0.338307</iyy>
            <iyz>-1.20641e-05</iyz>
            <izz>0.36304</izz>
          </inertia>
        </inertial>
        <collision name='base_link_collision'>
          <pose>0 0 0 0 -0 0</pose>
          <geometry>
            <mesh>
              <scale>1 1 1</scale>
              <uri>file:///home/rhex/mnt/rhex_ws/install/rhex_description/share/rhex_description/meshes/rpk10_chassis.dae</uri>
            </mesh>
          </geometry>
          <surface>
            <contact>
              <ode/>
            </contact>
            <friction>
              <ode/>
              <torsional>
                <ode/>
              </torsional>
            </friction>
            <bounce/>
          </surface>
          <max_contacts>10</max_contacts>
        </collision>
        <collision name='base_link_fixed_joint_lump__upper_case_link_collision_1'>
          <pose>0 0 0.055 0 -0 0</pose>
          <geometry>
            <mesh>
              <scale>0.001 0.001 0.001</scale>
              <uri>file:///home/rhex/mnt/rhex_ws/install/rhex_description/share/rhex_description/meshes/upper_case.dae</uri>
            </mesh>
          </geometry>
          <max_contacts>10</max_contacts>
          <surface>
            <contact>
              <ode/>
            </contact>
            <bounce/>
            <friction>
              <torsional>
                <ode/>
              </torsional>
              <ode/>
            </friction>
          </surface>
        </collision>
        <collision name='base_link_fixed_joint_lump__camera_link_collision_2'>
          <pose>0.267 0.0055 0.1155 0 -0 0</pose>
          <geometry>
            <box>
              <size>0.015 0.0867 0.022</size>
            </box>
          </geometry>
          <surface>
            <contact>
              <ode/>
            </contact>
            <friction>
              <ode/>
              <torsional>
                <ode/>
              </torsional>
            </friction>
            <bounce/>
          </surface>
          <max_contacts>10</max_contacts>
        </collision>
        <collision name='base_link_fixed_joint_lump__imu_link_collision_3'>
          <pose>0.267 -0.005 0.0885 0 -0 0</pose>
          <geometry>
            <box>
              <size>0.015 0.115 0.02</size>
            </box>
          </geometry>
          <surface>
            <contact>
              <ode/>
            </contact>
            <friction>
              <ode/>
              <torsional>
                <ode/>
              </torsional>
            </friction>
            <bounce/>
          </surface>
          <max_contacts>10</max_contacts>
        </collision>
        <collision name='base_link_fixed_joint_lump__lidar_link_collision_4'>
          <pose>0 0 0.172 0 -0 0</pose>
          <geometry>
            <cylinder>
              <length>0.056</length>
              <radius>0.0508</radius>
            </cylinder>
          </geometry>
          <surface>
            <contact>
              <ode/>
            </contact>
            <friction>
              <ode/>
              <torsional>
                <ode/>
              </torsional>
            </friction>
            <bounce/>
          </surface>
          <max_contacts>10</max_contacts>
        </collision>
        <visual name='base_link_visual'>
          <pose>0 0 0 0 -0 0</pose>
          <geometry>
            <mesh>
              <scale>1 1 1</scale>
              <uri>file:///home/rhex/mnt/rhex_ws/install/rhex_description/share/rhex_description/meshes/rpk10_chassis.dae</uri>
            </mesh>
          </geometry>
          <material>
            <script>
              <name>Gazebo/Red</name>
              <uri>file://media/materials/scripts/gazebo.material</uri>
            </script>
          </material>
        </visual>
        <visual name='base_link_fixed_joint_lump__upper_case_link_visual_1'>
          <pose>0 0 0.055 0 -0 0</pose>
          <geometry>
            <mesh>
              <scale>0.001 0.001 0.001</scale>
              <uri>file:///home/rhex/mnt/rhex_ws/install/rhex_description/share/rhex_description/meshes/upper_case.dae</uri>
            </mesh>
          </geometry>
        </visual>
        <visual name='base_link_fixed_joint_lump__camera_link_visual_2'>
          <pose>0.267 0.0055 0.1155 0 -0 0</pose>
          <geometry>
            <box>
              <size>0.015 0.0867 0.022</size>
            </box>
          </geometry>
        </visual>
        <visual name='base_link_fixed_joint_lump__imu_link_visual_3'>
          <pose>0.267 -0.005 0.0885 0 -0 0</pose>
          <geometry>
            <box>
              <size>0.015 0.115 0.02</size>
            </box>
          </geometry>
        </visual>
        <visual name='base_link_fixed_joint_lump__lidar_link_visual_4'>
          <pose>0 0 0.172 0 -0 0</pose>
          <geometry>
            <cylinder>
              <length>0.056</length>
              <radius>0.0508</radius>
            </cylinder>
          </geometry>
        </visual>
        <sensor name='depth_camera' type='depth'>
          <visualize>1</visualize>
          <update_rate>30</update_rate>
          <camera name='camera'>
            <horizontal_fov>1.0472</horizontal_fov>
            <image>
              <width>640</width>
              <height>480</height>
              <format>B8G8R8</format>
            </image>
            <clip>
              <near>0.05</near>
              <far>30</far>
            </clip>
            <noise>
              <type>gaussian</type>
              <mean>0</mean>
              <stddev>0.007</stddev>
            </noise>
          </camera>
          <plugin name='depth_camera_controller' filename='libgazebo_ros_camera.so'>
            <update_rate>0.0</update_rate>
            <frame_name>camera_depth_frame</frame_name>
            <min_depth>0.2</min_depth>
            <max_depth>4.0</max_depth>
          </plugin>
          <pose>0.267 0.0055 0.1155 0 -0 0</pose>
        </sensor>
        <sensor name='imu_sensor' type='imu'>
          <plugin name='imu_plugin' filename='libgazebo_ros_imu_sensor.so'>
            <ros>
              <namespace>/imu</namespace>
              <remapping>~/out:=data</remapping>
            </ros>
            <initial_orientation_as_reference>0</initial_orientation_as_reference>
          </plugin>
          <always_on>1</always_on>
          <update_rate>1000</update_rate>
          <visualize>1</visualize>
          <imu>
            <angular_velocity>
              <x>
                <noise type='gaussian'>
                  <mean>0</mean>
                  <stddev>0.0002</stddev>
                  <bias_mean>7.5e-06</bias_mean>
                  <bias_stddev>8e-07</bias_stddev>
                </noise>
              </x>
              <y>
                <noise type='gaussian'>
                  <mean>0</mean>
                  <stddev>0.0002</stddev>
                  <bias_mean>7.5e-06</bias_mean>
                  <bias_stddev>8e-07</bias_stddev>
                </noise>
              </y>
              <z>
                <noise type='gaussian'>
                  <mean>0</mean>
                  <stddev>0.0002</stddev>
                  <bias_mean>7.5e-06</bias_mean>
                  <bias_stddev>8e-07</bias_stddev>
                </noise>
              </z>
            </angular_velocity>
            <linear_acceleration>
              <x>
                <noise type='gaussian'>
                  <mean>0</mean>
                  <stddev>0.017</stddev>
                  <bias_mean>0.1</bias_mean>
                  <bias_stddev>0.001</bias_stddev>
                </noise>
              </x>
              <y>
                <noise type='gaussian'>
                  <mean>0</mean>
                  <stddev>0.017</stddev>
                  <bias_mean>0.1</bias_mean>
                  <bias_stddev>0.001</bias_stddev>
                </noise>
              </y>
              <z>
                <noise type='gaussian'>
                  <mean>0</mean>
                  <stddev>0.017</stddev>
                  <bias_mean>0.1</bias_mean>
                  <bias_stddev>0.001</bias_stddev>
                </noise>
              </z>
            </linear_acceleration>
          </imu>
          <pose>0.267 -0.005 0.0885 0 -0 0</pose>
        </sensor>
        <sensor name='lidar' type='ray'>
          <always_on>1</always_on>
          <visualize>0</visualize>
          <update_rate>5</update_rate>
          <ray>
            <scan>
              <horizontal>
                <samples>360</samples>
                <resolution>1</resolution>
                <min_angle>0</min_angle>
                <max_angle>6.28</max_angle>
              </horizontal>
              <vertical>
                <samples>1</samples>
                <min_angle>0</min_angle>
                <max_angle>0</max_angle>
              </vertical>
            </scan>
            <range>
              <min>0.12</min>
              <max>3.5</max>
              <resolution>0.015</resolution>
            </range>
            <noise>
              <type>gaussian</type>
              <mean>0</mean>
              <stddev>0.01</stddev>
            </noise>
          </ray>
          <plugin name='scan' filename='libgazebo_ros_ray_sensor.so'>
            <ros>
              <remapping>~/out:=scan</remapping>
            </ros>
            <output_type>sensor_msgs/LaserScan</output_type>
            <frame_name>lidar_link</frame_name>
          </plugin>
          <pose>0 0 0.172 0 -0 0</pose>
        </sensor>
        <self_collide>0</self_collide>
        <enable_wind>0</enable_wind>
        <kinematic>0</kinematic>
      </link>
      <joint name='front_left_joint' type='revolute'>
        <pose relative_to='base_link'>0.19 0.1235 0 0 -0 0</pose>
        <parent>base_link</parent>
        <child>front_left_link</child>
        <axis>
          <xyz>0 1 0</xyz>
          <limit>
            <lower>-1e+16</lower>
            <upper>1e+16</upper>
          </limit>
          <dynamics>
            <damping>0.5</damping>
            <friction>0</friction>
            <spring_reference>0</spring_reference>
            <spring_stiffness>0</spring_stiffness>
          </dynamics>
        </axis>
      </joint>
      <link name='front_left_link'>
        <pose relative_to='front_left_joint'>0 0 0 0 -0 0</pose>
        <inertial>
          <pose>0 0 -0.08 0 -0 0</pose>
          <mass>0.05</mass>
          <inertia>
            <ixx>0.000130865</ixx>
            <ixy>0</ixy>
            <ixz>0</ixz>
            <iyy>0.000166666</iyy>
            <iyz>0</iyz>
            <izz>4.40694e-05</izz>
          </inertia>
        </inertial>
        <collision name='front_left_link_collision'>
          <pose>0 0 0 0 -0 0</pose>
          <geometry>
            <mesh>
              <scale>1 1 1</scale>
              <uri>file:///home/rhex/mnt/rhex_ws/install/rhex_description/share/rhex_description/meshes/rpk10_leg.dae</uri>
            </mesh>
          </geometry>
          <surface>
            <contact>
              <ode>
                <kp>1e+12</kp>
                <kd>100</kd>
                <min_depth>0.05</min_depth>
              </ode>
            </contact>
            <friction>
              <ode>
                <mu>50</mu>
                <mu2>50</mu2>
              </ode>
              <torsional>
                <ode/>
              </torsional>
            </friction>
            <bounce/>
          </surface>
          <max_contacts>10</max_contacts>
        </collision>
        <visual name='front_left_link_visual'>
          <pose>0 0 0 0 -0 0</pose>
          <geometry>
            <mesh>
              <scale>1 1 1</scale>
              <uri>file:///home/rhex/mnt/rhex_ws/install/rhex_description/share/rhex_description/meshes/rpk10_leg.dae</uri>
            </mesh>
          </geometry>
        </visual>
        <self_collide>0</self_collide>
        <enable_wind>0</enable_wind>
        <kinematic>0</kinematic>
      </link>
      <joint name='front_right_joint' type='revolute'>
        <pose relative_to='base_link'>0.19 -0.1235 0 0 -0 0</pose>
        <parent>base_link</parent>
        <child>front_right_link</child>
        <axis>
          <xyz>0 1 0</xyz>
          <limit>
            <lower>-1e+16</lower>
            <upper>1e+16</upper>
          </limit>
          <dynamics>
            <damping>0.5</damping>
            <friction>0</friction>
            <spring_reference>0</spring_reference>
            <spring_stiffness>0</spring_stiffness>
          </dynamics>
        </axis>
      </joint>
      <link name='front_right_link'>
        <pose relative_to='front_right_joint'>0 0 0 0 -0 0</pose>
        <inertial>
          <pose>0 0 -0.08 0 -0 0</pose>
          <mass>0.05</mass>
          <inertia>
            <ixx>0.000130865</ixx>
            <ixy>0</ixy>
            <ixz>0</ixz>
            <iyy>0.000166666</iyy>
            <iyz>0</iyz>
            <izz>4.40694e-05</izz>
          </inertia>
        </inertial>
        <collision name='front_right_link_collision'>
          <pose>0 0 0 0 -0 0</pose>
          <geometry>
            <mesh>
              <scale>1 1 1</scale>
              <uri>file:///home/rhex/mnt/rhex_ws/install/rhex_description/share/rhex_description/meshes/rpk10_leg.dae</uri>
            </mesh>
          </geometry>
          <surface>
            <contact>
              <ode>
                <kp>1e+12</kp>
                <kd>100</kd>
                <min_depth>0.05</min_depth>
              </ode>
            </contact>
            <friction>
              <ode>
                <mu>50</mu>
                <mu2>50</mu2>
              </ode>
              <torsional>
                <ode/>
              </torsional>
            </friction>
            <bounce/>
          </surface>
          <max_contacts>10</max_contacts>
        </collision>
        <visual name='front_right_link_visual'>
          <pose>0 0 0 0 -0 0</pose>
          <geometry>
            <mesh>
              <scale>1 1 1</scale>
              <uri>file:///home/rhex/mnt/rhex_ws/install/rhex_description/share/rhex_description/meshes/rpk10_leg.dae</uri>
            </mesh>
          </geometry>
        </visual>
        <self_collide>0</self_collide>
        <enable_wind>0</enable_wind>
        <kinematic>0</kinematic>
      </link>
      <joint name='mid_left_joint' type='revolute'>
        <pose relative_to='base_link'>0 0.162 0 0 -0 0</pose>
        <parent>base_link</parent>
        <child>mid_left_link</child>
        <axis>
          <xyz>0 1 0</xyz>
          <limit>
            <lower>-1e+16</lower>
            <upper>1e+16</upper>
          </limit>
          <dynamics>
            <damping>0.5</damping>
            <friction>0</friction>
            <spring_reference>0</spring_reference>
            <spring_stiffness>0</spring_stiffness>
          </dynamics>
        </axis>
      </joint>
      <link name='mid_left_link'>
        <pose relative_to='mid_left_joint'>0 0 0 0 -0 0</pose>
        <inertial>
          <pose>0 0 -0.08 0 -0 0</pose>
          <mass>0.05</mass>
          <inertia>
            <ixx>0.000130865</ixx>
            <ixy>0</ixy>
            <ixz>0</ixz>
            <iyy>0.000166666</iyy>
            <iyz>0</iyz>
            <izz>4.40694e-05</izz>
          </inertia>
        </inertial>
        <collision name='mid_left_link_collision'>
          <pose>0 0 0 0 -0 0</pose>
          <geometry>
            <mesh>
              <scale>1 1 1</scale>
              <uri>file:///home/rhex/mnt/rhex_ws/install/rhex_description/share/rhex_description/meshes/rpk10_leg.dae</uri>
            </mesh>
          </geometry>
          <surface>
            <contact>
              <ode>
                <kp>1e+12</kp>
                <kd>100</kd>
                <min_depth>0.05</min_depth>
              </ode>
            </contact>
            <friction>
              <ode>
                <mu>50</mu>
                <mu2>50</mu2>
              </ode>
              <torsional>
                <ode/>
              </torsional>
            </friction>
            <bounce/>
          </surface>
          <max_contacts>10</max_contacts>
        </collision>
        <visual name='mid_left_link_visual'>
          <pose>0 0 0 0 -0 0</pose>
          <geometry>
            <mesh>
              <scale>1 1 1</scale>
              <uri>file:///home/rhex/mnt/rhex_ws/install/rhex_description/share/rhex_description/meshes/rpk10_leg.dae</uri>
            </mesh>
          </geometry>
        </visual>
        <self_collide>0</self_collide>
        <enable_wind>0</enable_wind>
        <kinematic>0</kinematic>
      </link>
      <joint name='mid_right_joint' type='revolute'>
        <pose relative_to='base_link'>0 -0.162 0 0 -0 0</pose>
        <parent>base_link</parent>
        <child>mid_right_link</child>
        <axis>
          <xyz>0 1 0</xyz>
          <limit>
            <lower>-1e+16</lower>
            <upper>1e+16</upper>
          </limit>
          <dynamics>
            <damping>0.5</damping>
            <friction>0</friction>
            <spring_reference>0</spring_reference>
            <spring_stiffness>0</spring_stiffness>
          </dynamics>
        </axis>
      </joint>
      <link name='mid_right_link'>
        <pose relative_to='mid_right_joint'>0 0 0 0 -0 0</pose>
        <inertial>
          <pose>0 0 -0.08 0 -0 0</pose>
          <mass>0.05</mass>
          <inertia>
            <ixx>0.000130865</ixx>
            <ixy>0</ixy>
            <ixz>0</ixz>
            <iyy>0.000166666</iyy>
            <iyz>0</iyz>
            <izz>4.40694e-05</izz>
          </inertia>
        </inertial>
        <collision name='mid_right_link_collision'>
          <pose>0 0 0 0 -0 0</pose>
          <geometry>
            <mesh>
              <scale>1 1 1</scale>
              <uri>file:///home/rhex/mnt/rhex_ws/install/rhex_description/share/rhex_description/meshes/rpk10_leg.dae</uri>
            </mesh>
          </geometry>
          <surface>
            <contact>
              <ode>
                <kp>1e+12</kp>
                <kd>100</kd>
                <min_depth>0.05</min_depth>
              </ode>
            </contact>
            <friction>
              <ode>
                <mu>50</mu>
                <mu2>50</mu2>
              </ode>
              <torsional>
                <ode/>
              </torsional>
            </friction>
            <bounce/>
          </surface>
          <max_contacts>10</max_contacts>
        </collision>
        <visual name='mid_right_link_visual'>
          <pose>0 0 0 0 -0 0</pose>
          <geometry>
            <mesh>
              <scale>1 1 1</scale>
              <uri>file:///home/rhex/mnt/rhex_ws/install/rhex_description/share/rhex_description/meshes/rpk10_leg.dae</uri>
            </mesh>
          </geometry>
        </visual>
        <self_collide>0</self_collide>
        <enable_wind>0</enable_wind>
        <kinematic>0</kinematic>
      </link>
      <joint name='rear_left_joint' type='revolute'>
        <pose relative_to='base_link'>-0.19 0.1235 0 0 -0 0</pose>
        <parent>base_link</parent>
        <child>rear_left_link</child>
        <axis>
          <xyz>0 1 0</xyz>
          <limit>
            <lower>-1e+16</lower>
            <upper>1e+16</upper>
          </limit>
          <dynamics>
            <damping>0.5</damping>
            <friction>0</friction>
            <spring_reference>0</spring_reference>
            <spring_stiffness>0</spring_stiffness>
          </dynamics>
        </axis>
      </joint>
      <link name='rear_left_link'>
        <pose relative_to='rear_left_joint'>0 0 0 0 -0 0</pose>
        <inertial>
          <pose>0 0 -0.08 0 -0 0</pose>
          <mass>0.05</mass>
          <inertia>
            <ixx>0.000130865</ixx>
            <ixy>0</ixy>
            <ixz>0</ixz>
            <iyy>0.000166666</iyy>
            <iyz>0</iyz>
            <izz>4.40694e-05</izz>
          </inertia>
        </inertial>
        <collision name='rear_left_link_collision'>
          <pose>0 0 0 0 -0 0</pose>
          <geometry>
            <mesh>
              <scale>1 1 1</scale>
              <uri>file:///home/rhex/mnt/rhex_ws/install/rhex_description/share/rhex_description/meshes/rpk10_leg.dae</uri>
            </mesh>
          </geometry>
          <surface>
            <contact>
              <ode>
                <kp>1e+12</kp>
                <kd>100</kd>
                <min_depth>0.05</min_depth>
              </ode>
            </contact>
            <friction>
              <ode>
                <mu>50</mu>
                <mu2>50</mu2>
              </ode>
              <torsional>
                <ode/>
              </torsional>
            </friction>
            <bounce/>
          </surface>
          <max_contacts>10</max_contacts>
        </collision>
        <visual name='rear_left_link_visual'>
          <pose>0 0 0 0 -0 0</pose>
          <geometry>
            <mesh>
              <scale>1 1 1</scale>
              <uri>file:///home/rhex/mnt/rhex_ws/install/rhex_description/share/rhex_description/meshes/rpk10_leg.dae</uri>
            </mesh>
          </geometry>
        </visual>
        <self_collide>0</self_collide>
        <enable_wind>0</enable_wind>
        <kinematic>0</kinematic>
      </link>
      <joint name='rear_right_joint' type='revolute'>
        <pose relative_to='base_link'>-0.19 -0.1235 0 0 -0 0</pose>
        <parent>base_link</parent>
        <child>rear_right_link</child>
        <axis>
          <xyz>0 1 0</xyz>
          <limit>
            <lower>-1e+16</lower>
            <upper>1e+16</upper>
          </limit>
          <dynamics>
            <damping>0.5</damping>
            <friction>0</friction>
            <spring_reference>0</spring_reference>
            <spring_stiffness>0</spring_stiffness>
          </dynamics>
        </axis>
      </joint>
      <link name='rear_right_link'>
        <pose relative_to='rear_right_joint'>0 0 0 0 -0 0</pose>
        <inertial>
          <pose>0 0 -0.08 0 -0 0</pose>
          <mass>0.05</mass>
          <inertia>
            <ixx>0.000130865</ixx>
            <ixy>0</ixy>
            <ixz>0</ixz>
            <iyy>0.000166666</iyy>
            <iyz>0</iyz>
            <izz>4.40694e-05</izz>
          </inertia>
        </inertial>
        <collision name='rear_right_link_collision'>
          <pose>0 0 0 0 -0 0</pose>
          <geometry>
            <mesh>
              <scale>1 1 1</scale>
              <uri>file:///home/rhex/mnt/rhex_ws/install/rhex_description/share/rhex_description/meshes/rpk10_leg.dae</uri>
            </mesh>
          </geometry>
          <surface>
            <contact>
              <ode>
                <kp>1e+12</kp>
                <kd>100</kd>
                <min_depth>0.05</min_depth>
              </ode>
            </contact>
            <friction>
              <ode>
                <mu>50</mu>
                <mu2>50</mu2>
              </ode>
              <torsional>
                <ode/>
              </torsional>
            </friction>
            <bounce/>
          </surface>
          <max_contacts>10</max_contacts>
        </collision>
        <visual name='rear_right_link_visual'>
          <pose>0 0 0 0 -0 0</pose>
          <geometry>
            <mesh>
              <scale>1 1 1</scale>
              <uri>file:///home/rhex/mnt/rhex_ws/install/rhex_description/share/rhex_description/meshes/rpk10_leg.dae</uri>
            </mesh>
          </geometry>
        </visual>
        <self_collide>0</self_collide>
        <enable_wind>0</enable_wind>
        <kinematic>0</kinematic>
      </link>
      <plugin name='p3d_base_controller' filename='libgazebo_ros_p3d.so'>
        <ros>
          <argument>/odom:=odom/robot_pos</argument>
        </ros>
        <body_name>base_link</body_name>
        <frame_name>world</frame_name>
        <update_rate>30.0</update_rate>
        <xyz_offset>0 0 0</xyz_offset>
        <rpy_offset>0 0 0</rpy_offset>
        <gaussian_noise>0.01</gaussian_noise>
      </plugin>
      <static>0</static>
      <plugin name='gazebo_ros2_control' filename='libgazebo_ros2_control.so'>
        <parameters>/home/rhex/mnt/rhex_ws/install/rhex_description/share/rhex_description/config/ros_control.yaml</parameters>
      </plugin>
      <pose>0 0 0.1 0 -0 0</pose>
    </model>
    <model name='person_standing'>
      <link name='link'>
        <inertial>
          <pose>0 -0.1 0.95 0 -0 0</pose>
          <mass>80</mass>
          <inertia>
            <ixx>24.88</ixx>
            <ixy>0</ixy>
            <ixz>0</ixz>
            <iyy>25.73</iyy>
            <iyz>0</iyz>
            <izz>2.48</izz>
          </inertia>
        </inertial>
        <collision name='bottom'>
          <pose>0 -0.1 0.01 0 -0 0</pose>
          <geometry>
            <box>
              <size>0.5 0.35 0.02</size>
            </box>
          </geometry>
          <max_contacts>10</max_contacts>
          <surface>
            <contact>
              <ode/>
            </contact>
            <bounce/>
            <friction>
              <torsional>
                <ode/>
              </torsional>
              <ode/>
            </friction>
          </surface>
        </collision>
        <collision name='person'>
          <pose>0 0 0.02 0.04 -0 0</pose>
          <geometry>
            <mesh>
              <uri>model://person_standing/meshes/standing.dae</uri>
            </mesh>
          </geometry>
          <max_contacts>10</max_contacts>
          <surface>
            <contact>
              <ode/>
            </contact>
            <bounce/>
            <friction>
              <torsional>
                <ode/>
              </torsional>
              <ode/>
            </friction>
          </surface>
        </collision>
        <visual name='visual'>
          <pose>0 0 0.02 0.04 -0 0</pose>
          <geometry>
            <mesh>
              <uri>model://person_standing/meshes/standing.dae</uri>
            </mesh>
          </geometry>
        </visual>
        <self_collide>0</self_collide>
        <enable_wind>0</enable_wind>
        <kinematic>0</kinematic>
      </link>
      <pose>8.68895 3.19623 0 0 -0 0</pose>
    </model>
    <model name='person_walking'>
      <link name='link'>
        <inertial>
          <pose>0 0 0.95 0 -0 0</pose>
          <mass>80</mass>
          <inertia>
            <ixx>27.82</ixx>
            <ixy>0</ixy>
            <ixz>0</ixz>
            <iyy>24.88</iyy>
            <iyz>0</iyz>
            <izz>4.57</izz>
          </inertia>
        </inertial>
        <collision name='bottom'>
          <pose>0 0 0.01 0 -0 0</pose>
          <geometry>
            <box>
              <size>0.35 0.75 0.02</size>
            </box>
          </geometry>
          <max_contacts>10</max_contacts>
          <surface>
            <contact>
              <ode/>
            </contact>
            <bounce/>
            <friction>
              <torsional>
                <ode/>
              </torsional>
              <ode/>
            </friction>
          </surface>
        </collision>
        <collision name='person'>
          <pose>0 0 -0.02 0 -0 0</pose>
          <geometry>
            <mesh>
              <uri>model://person_walking/meshes/walking.dae</uri>
            </mesh>
          </geometry>
          <max_contacts>10</max_contacts>
          <surface>
            <contact>
              <ode/>
            </contact>
            <bounce/>
            <friction>
              <torsional>
                <ode/>
              </torsional>
              <ode/>
            </friction>
          </surface>
        </collision>
        <visual name='visual'>
          <pose>0 0 -0.02 0 -0 0</pose>
          <geometry>
            <mesh>
              <uri>model://person_walking/meshes/walking.dae</uri>
            </mesh>
          </geometry>
        </visual>
        <self_collide>0</self_collide>
        <enable_wind>0</enable_wind>
        <kinematic>0</kinematic>
      </link>
      <pose>8.29359 -1.4313 0 0 -0 0</pose>
    </model>
  </world>
</sdf>
