<sdf version='1.7'>
  <world name='default'>
    <plugin name='gazebo_ros_state' filename='libgazebo_ros_state.so'>
      <ros>
        <namespace>/gazebo</namespace>
      </ros>
      <update_rate>1000</update_rate>
    </plugin>
    <light name='sun' type='directional'>
      <cast_shadows>1</cast_shadows>
      <pose>0 0 10 0 -0 0</pose>
      <diffuse>1 1 1 1</diffuse>
      <specular>1 1 1 1</specular>
      <attenuation>
        <range>1000</range>
        <constant>0.9</constant>
        <linear>0.01</linear>
        <quadratic>0.001</quadratic>
      </attenuation>
      <direction>-0.5 0.1 -0.9</direction>
      <spot>
        <inner_angle>0</inner_angle>
        <outer_angle>0</outer_angle>
        <falloff>0</falloff>
      </spot>
    </light>
    <model name='ground_plane'>
      <static>1</static>
      <link name='link'>
        <collision name='collision'>
          <geometry>
            <plane>
              <normal>0 0 1</normal>
              <size>100 100</size>
            </plane>
          </geometry>
          <surface>
            <contact>
              <collide_bitmask>65535</collide_bitmask>
              <ode/>
            </contact>
            <friction>
              <ode>
                <mu>100</mu>
                <mu2>50</mu2>
              </ode>
              <torsional>
                <ode/>
              </torsional>
            </friction>
            <bounce/>
          </surface>
          <max_contacts>10</max_contacts>
        </collision>
        <visual name='visual'>
          <cast_shadows>0</cast_shadows>
          <geometry>
            <plane>
              <normal>0 0 1</normal>
              <size>100 100</size>
            </plane>
          </geometry>
          <material>
            <script>
              <uri>file://media/materials/scripts/gazebo.material</uri>
              <name>Gazebo/Grey</name>
            </script>
          </material>
        </visual>
        <self_collide>0</self_collide>
        <enable_wind>0</enable_wind>
        <kinematic>0</kinematic>
      </link>
    </model>
    <gravity>0 0 -9.8</gravity>
    <magnetic_field>6e-06 2.3e-05 -4.2e-05</magnetic_field>
    <atmosphere type='adiabatic'/>
    <physics type='ode'>
      <max_step_size>0.001</max_step_size>
      <real_time_factor>1</real_time_factor>
      <real_time_update_rate>1000</real_time_update_rate>
    </physics>
    <scene>
      <ambient>0.4 0.4 0.4 1</ambient>
      <background>0.7 0.7 0.7 1</background>
      <shadows>1</shadows>
    </scene>
    <audio>
      <device>default</device>
    </audio>
    <wind/>
    <spherical_coordinates>
      <surface_model>EARTH_WGS84</surface_model>
      <latitude_deg>0</latitude_deg>
      <longitude_deg>0</longitude_deg>
      <elevation>0</elevation>
      <heading_deg>0</heading_deg>
    </spherical_coordinates>
    <model name='rhex'>
      <link name='base_link'>
        <inertial>
          <pose>0.000443 8e-06 0.00189 0 -0 0</pose>
          <mass>12.646</mass>
          <inertia>
            <ixx>0.0587881</ixx>
            <ixy>-2.79884e-05</ixy>
            <ixz>-0.000629803</ixz>
            <iyy>0.338307</iyy>
            <iyz>-1.20641e-05</iyz>
            <izz>0.36304</izz>
          </inertia>
        </inertial>
        <collision name='base_link_collision'>
          <pose>0 0 0 0 -0 0</pose>
          <geometry>
            <mesh>
              <scale>1 1 1</scale>
              <uri>file:///home/rhex/mnt/rhex_ws/install/rhex_description/share/rhex_description/meshes/rpk10_chassis.dae</uri>
            </mesh>
          </geometry>
          <surface>
            <contact>
              <ode/>
            </contact>
            <friction>
              <ode/>
              <torsional>
                <ode/>
              </torsional>
            </friction>
            <bounce/>
          </surface>
          <max_contacts>10</max_contacts>
        </collision>
        <collision name='base_link_fixed_joint_lump__upper_case_link_collision_1'>
          <pose>0 0 0.055 0 -0 0</pose>
          <geometry>
            <mesh>
              <scale>0.001 0.001 0.001</scale>
              <uri>file:///home/rhex/mnt/rhex_ws/install/rhex_description/share/rhex_description/meshes/upper_case.dae</uri>
            </mesh>
          </geometry>
          <max_contacts>10</max_contacts>
          <surface>
            <contact>
              <ode/>
            </contact>
            <bounce/>
            <friction>
              <torsional>
                <ode/>
              </torsional>
              <ode/>
            </friction>
          </surface>
        </collision>
        <collision name='base_link_fixed_joint_lump__camera_link_collision_2'>
          <pose>0.267 0.0055 0.1155 0 -0 0</pose>
          <geometry>
            <box>
              <size>0.015 0.0867 0.022</size>
            </box>
          </geometry>
          <surface>
            <contact>
              <ode/>
            </contact>
            <friction>
              <ode/>
              <torsional>
                <ode/>
              </torsional>
            </friction>
            <bounce/>
          </surface>
          <max_contacts>10</max_contacts>
        </collision>
        <collision name='base_link_fixed_joint_lump__imu_link_collision_3'>
          <pose>0.267 -0.005 0.0885 0 -0 0</pose>
          <geometry>
            <box>
              <size>0.015 0.115 0.02</size>
            </box>
          </geometry>
          <surface>
            <contact>
              <ode/>
            </contact>
            <friction>
              <ode/>
              <torsional>
                <ode/>
              </torsional>
            </friction>
            <bounce/>
          </surface>
          <max_contacts>10</max_contacts>
        </collision>
        <collision name='base_link_fixed_joint_lump__lidar_link_collision_4'>
          <pose>0 0 0.172 0 -0 0</pose>
          <geometry>
            <cylinder>
              <length>0.056</length>
              <radius>0.0508</radius>
            </cylinder>
          </geometry>
          <surface>
            <contact>
              <ode/>
            </contact>
            <friction>
              <ode/>
              <torsional>
                <ode/>
              </torsional>
            </friction>
            <bounce/>
          </surface>
          <max_contacts>10</max_contacts>
        </collision>
        <visual name='base_link_visual'>
          <pose>0 0 0 0 -0 0</pose>
          <geometry>
            <mesh>
              <scale>1 1 1</scale>
              <uri>file:///home/rhex/mnt/rhex_ws/install/rhex_description/share/rhex_description/meshes/rpk10_chassis.dae</uri>
            </mesh>
          </geometry>
          <material>
            <script>
              <name>Gazebo/Red</name>
              <uri>file://media/materials/scripts/gazebo.material</uri>
            </script>
          </material>
        </visual>
        <visual name='base_link_fixed_joint_lump__upper_case_link_visual_1'>
          <pose>0 0 0.055 0 -0 0</pose>
          <geometry>
            <mesh>
              <scale>0.001 0.001 0.001</scale>
              <uri>file:///home/rhex/mnt/rhex_ws/install/rhex_description/share/rhex_description/meshes/upper_case.dae</uri>
            </mesh>
          </geometry>
        </visual>
        <visual name='base_link_fixed_joint_lump__camera_link_visual_2'>
          <pose>0.267 0.0055 0.1155 0 -0 0</pose>
          <geometry>
            <box>
              <size>0.015 0.0867 0.022</size>
            </box>
          </geometry>
        </visual>
        <visual name='base_link_fixed_joint_lump__imu_link_visual_3'>
          <pose>0.267 -0.005 0.0885 0 -0 0</pose>
          <geometry>
            <box>
              <size>0.015 0.115 0.02</size>
            </box>
          </geometry>
        </visual>
        <visual name='base_link_fixed_joint_lump__lidar_link_visual_4'>
          <pose>0 0 0.172 0 -0 0</pose>
          <geometry>
            <cylinder>
              <length>0.056</length>
              <radius>0.0508</radius>
            </cylinder>
          </geometry>
        </visual>
        <sensor name='depth_camera' type='depth'>
          <visualize>1</visualize>
          <update_rate>30</update_rate>
          <camera name='camera'>
            <horizontal_fov>1.0472</horizontal_fov>
            <image>
              <width>640</width>
              <height>480</height>
              <format>B8G8R8</format>
            </image>
            <clip>
              <near>0.05</near>
              <far>30</far>
            </clip>
            <noise>
              <type>gaussian</type>
              <mean>0</mean>
              <stddev>0.007</stddev>
            </noise>
          </camera>
          <plugin name='depth_camera_controller' filename='libgazebo_ros_camera.so'>
            <update_rate>0.0</update_rate>
            <frame_name>camera_depth_frame</frame_name>
            <min_depth>0.2</min_depth>
            <max_depth>4.0</max_depth>
          </plugin>
          <pose>0.267 0.0055 0.1155 0 -0 0</pose>
        </sensor>
        <sensor name='imu_sensor' type='imu'>
          <plugin name='imu_plugin' filename='libgazebo_ros_imu_sensor.so'>
            <ros>
              <namespace>/imu</namespace>
              <remapping>~/out:=data</remapping>
            </ros>
            <initial_orientation_as_reference>0</initial_orientation_as_reference>
          </plugin>
          <always_on>1</always_on>
          <update_rate>1000</update_rate>
          <visualize>1</visualize>
          <imu>
            <angular_velocity>
              <x>
                <noise type='gaussian'>
                  <mean>0</mean>
                  <stddev>0.0002</stddev>
                  <bias_mean>7.5e-06</bias_mean>
                  <bias_stddev>8e-07</bias_stddev>
                </noise>
              </x>
              <y>
                <noise type='gaussian'>
                  <mean>0</mean>
                  <stddev>0.0002</stddev>
                  <bias_mean>7.5e-06</bias_mean>
                  <bias_stddev>8e-07</bias_stddev>
                </noise>
              </y>
              <z>
                <noise type='gaussian'>
                  <mean>0</mean>
                  <stddev>0.0002</stddev>
                  <bias_mean>7.5e-06</bias_mean>
                  <bias_stddev>8e-07</bias_stddev>
                </noise>
              </z>
            </angular_velocity>
            <linear_acceleration>
              <x>
                <noise type='gaussian'>
                  <mean>0</mean>
                  <stddev>0.017</stddev>
                  <bias_mean>0.1</bias_mean>
                  <bias_stddev>0.001</bias_stddev>
                </noise>
              </x>
              <y>
                <noise type='gaussian'>
                  <mean>0</mean>
                  <stddev>0.017</stddev>
                  <bias_mean>0.1</bias_mean>
                  <bias_stddev>0.001</bias_stddev>
                </noise>
              </y>
              <z>
                <noise type='gaussian'>
                  <mean>0</mean>
                  <stddev>0.017</stddev>
                  <bias_mean>0.1</bias_mean>
                  <bias_stddev>0.001</bias_stddev>
                </noise>
              </z>
            </linear_acceleration>
          </imu>
          <pose>0.267 -0.005 0.0885 0 -0 0</pose>
        </sensor>
        <sensor name='lidar' type='ray'>
          <always_on>1</always_on>
          <visualize>0</visualize>
          <update_rate>5</update_rate>
          <ray>
            <scan>
              <horizontal>
                <samples>360</samples>
                <resolution>1</resolution>
                <min_angle>0</min_angle>
                <max_angle>6.28</max_angle>
              </horizontal>
              <vertical>
                <samples>1</samples>
                <min_angle>0</min_angle>
                <max_angle>0</max_angle>
              </vertical>
            </scan>
            <range>
              <min>0.12</min>
              <max>3.5</max>
              <resolution>0.015</resolution>
            </range>
            <noise>
              <type>gaussian</type>
              <mean>0</mean>
              <stddev>0.01</stddev>
            </noise>
          </ray>
          <plugin name='scan' filename='libgazebo_ros_ray_sensor.so'>
            <ros>
              <remapping>~/out:=scan</remapping>
            </ros>
            <output_type>sensor_msgs/LaserScan</output_type>
            <frame_name>lidar_link</frame_name>
          </plugin>
          <pose>0 0 0.172 0 -0 0</pose>
        </sensor>
        <self_collide>0</self_collide>
        <enable_wind>0</enable_wind>
        <kinematic>0</kinematic>
      </link>
      <joint name='front_left_joint' type='revolute'>
        <pose relative_to='base_link'>0.19 0.1235 0 0 -0 0</pose>
        <parent>base_link</parent>
        <child>front_left_link</child>
        <axis>
          <xyz>0 1 0</xyz>
          <limit>
            <lower>-1e+16</lower>
            <upper>1e+16</upper>
          </limit>
          <dynamics>
            <damping>0.5</damping>
            <friction>0</friction>
            <spring_reference>0</spring_reference>
            <spring_stiffness>0</spring_stiffness>
          </dynamics>
        </axis>
      </joint>
      <link name='front_left_link'>
        <pose relative_to='front_left_joint'>0 0 0 0 -0 0</pose>
        <inertial>
          <pose>0 0 -0.08 0 -0 0</pose>
          <mass>0.05</mass>
          <inertia>
            <ixx>0.000130865</ixx>
            <ixy>0</ixy>
            <ixz>0</ixz>
            <iyy>0.000166666</iyy>
            <iyz>0</iyz>
            <izz>4.40694e-05</izz>
          </inertia>
        </inertial>
        <collision name='front_left_link_collision'>
          <pose>0 0 0 0 -0 0</pose>
          <geometry>
            <mesh>
              <scale>1 1 1</scale>
              <uri>file:///home/rhex/mnt/rhex_ws/install/rhex_description/share/rhex_description/meshes/rpk10_leg.dae</uri>
            </mesh>
          </geometry>
          <surface>
            <contact>
              <ode>
                <kp>1e+12</kp>
                <kd>100</kd>
                <min_depth>0.05</min_depth>
              </ode>
            </contact>
            <friction>
              <ode>
                <mu>50</mu>
                <mu2>50</mu2>
              </ode>
              <torsional>
                <ode/>
              </torsional>
            </friction>
            <bounce/>
          </surface>
          <max_contacts>10</max_contacts>
        </collision>
        <visual name='front_left_link_visual'>
          <pose>0 0 0 0 -0 0</pose>
          <geometry>
            <mesh>
              <scale>1 1 1</scale>
              <uri>file:///home/rhex/mnt/rhex_ws/install/rhex_description/share/rhex_description/meshes/rpk10_leg.dae</uri>
            </mesh>
          </geometry>
        </visual>
        <self_collide>0</self_collide>
        <enable_wind>0</enable_wind>
        <kinematic>0</kinematic>
      </link>
      <joint name='front_right_joint' type='revolute'>
        <pose relative_to='base_link'>0.19 -0.1235 0 0 -0 0</pose>
        <parent>base_link</parent>
        <child>front_right_link</child>
        <axis>
          <xyz>0 1 0</xyz>
          <limit>
            <lower>-1e+16</lower>
            <upper>1e+16</upper>
          </limit>
          <dynamics>
            <damping>0.5</damping>
            <friction>0</friction>
            <spring_reference>0</spring_reference>
            <spring_stiffness>0</spring_stiffness>
          </dynamics>
        </axis>
      </joint>
      <link name='front_right_link'>
        <pose relative_to='front_right_joint'>0 0 0 0 -0 0</pose>
        <inertial>
          <pose>0 0 -0.08 0 -0 0</pose>
          <mass>0.05</mass>
          <inertia>
            <ixx>0.000130865</ixx>
            <ixy>0</ixy>
            <ixz>0</ixz>
            <iyy>0.000166666</iyy>
            <iyz>0</iyz>
            <izz>4.40694e-05</izz>
          </inertia>
        </inertial>
        <collision name='front_right_link_collision'>
          <pose>0 0 0 0 -0 0</pose>
          <geometry>
            <mesh>
              <scale>1 1 1</scale>
              <uri>file:///home/rhex/mnt/rhex_ws/install/rhex_description/share/rhex_description/meshes/rpk10_leg.dae</uri>
            </mesh>
          </geometry>
          <surface>
            <contact>
              <ode>
                <kp>1e+12</kp>
                <kd>100</kd>
                <min_depth>0.05</min_depth>
              </ode>
            </contact>
            <friction>
              <ode>
                <mu>50</mu>
                <mu2>50</mu2>
              </ode>
              <torsional>
                <ode/>
              </torsional>
            </friction>
            <bounce/>
          </surface>
          <max_contacts>10</max_contacts>
        </collision>
        <visual name='front_right_link_visual'>
          <pose>0 0 0 0 -0 0</pose>
          <geometry>
            <mesh>
              <scale>1 1 1</scale>
              <uri>file:///home/rhex/mnt/rhex_ws/install/rhex_description/share/rhex_description/meshes/rpk10_leg.dae</uri>
            </mesh>
          </geometry>
        </visual>
        <self_collide>0</self_collide>
        <enable_wind>0</enable_wind>
        <kinematic>0</kinematic>
      </link>
      <joint name='mid_left_joint' type='revolute'>
        <pose relative_to='base_link'>0 0.162 0 0 -0 0</pose>
        <parent>base_link</parent>
        <child>mid_left_link</child>
        <axis>
          <xyz>0 1 0</xyz>
          <limit>
            <lower>-1e+16</lower>
            <upper>1e+16</upper>
          </limit>
          <dynamics>
            <damping>0.5</damping>
            <friction>0</friction>
            <spring_reference>0</spring_reference>
            <spring_stiffness>0</spring_stiffness>
          </dynamics>
        </axis>
      </joint>
      <link name='mid_left_link'>
        <pose relative_to='mid_left_joint'>0 0 0 0 -0 0</pose>
        <inertial>
          <pose>0 0 -0.08 0 -0 0</pose>
          <mass>0.05</mass>
          <inertia>
            <ixx>0.000130865</ixx>
            <ixy>0</ixy>
            <ixz>0</ixz>
            <iyy>0.000166666</iyy>
            <iyz>0</iyz>
            <izz>4.40694e-05</izz>
          </inertia>
        </inertial>
        <collision name='mid_left_link_collision'>
          <pose>0 0 0 0 -0 0</pose>
          <geometry>
            <mesh>
              <scale>1 1 1</scale>
              <uri>file:///home/rhex/mnt/rhex_ws/install/rhex_description/share/rhex_description/meshes/rpk10_leg.dae</uri>
            </mesh>
          </geometry>
          <surface>
            <contact>
              <ode>
                <kp>1e+12</kp>
                <kd>100</kd>
                <min_depth>0.05</min_depth>
              </ode>
            </contact>
            <friction>
              <ode>
                <mu>50</mu>
                <mu2>50</mu2>
              </ode>
              <torsional>
                <ode/>
              </torsional>
            </friction>
            <bounce/>
          </surface>
          <max_contacts>10</max_contacts>
        </collision>
        <visual name='mid_left_link_visual'>
          <pose>0 0 0 0 -0 0</pose>
          <geometry>
            <mesh>
              <scale>1 1 1</scale>
              <uri>file:///home/rhex/mnt/rhex_ws/install/rhex_description/share/rhex_description/meshes/rpk10_leg.dae</uri>
            </mesh>
          </geometry>
        </visual>
        <self_collide>0</self_collide>
        <enable_wind>0</enable_wind>
        <kinematic>0</kinematic>
      </link>
      <joint name='mid_right_joint' type='revolute'>
        <pose relative_to='base_link'>0 -0.162 0 0 -0 0</pose>
        <parent>base_link</parent>
        <child>mid_right_link</child>
        <axis>
          <xyz>0 1 0</xyz>
          <limit>
            <lower>-1e+16</lower>
            <upper>1e+16</upper>
          </limit>
          <dynamics>
            <damping>0.5</damping>
            <friction>0</friction>
            <spring_reference>0</spring_reference>
            <spring_stiffness>0</spring_stiffness>
          </dynamics>
        </axis>
      </joint>
      <link name='mid_right_link'>
        <pose relative_to='mid_right_joint'>0 0 0 0 -0 0</pose>
        <inertial>
          <pose>0 0 -0.08 0 -0 0</pose>
          <mass>0.05</mass>
          <inertia>
            <ixx>0.000130865</ixx>
            <ixy>0</ixy>
            <ixz>0</ixz>
            <iyy>0.000166666</iyy>
            <iyz>0</iyz>
            <izz>4.40694e-05</izz>
          </inertia>
        </inertial>
        <collision name='mid_right_link_collision'>
          <pose>0 0 0 0 -0 0</pose>
          <geometry>
            <mesh>
              <scale>1 1 1</scale>
              <uri>file:///home/rhex/mnt/rhex_ws/install/rhex_description/share/rhex_description/meshes/rpk10_leg.dae</uri>
            </mesh>
          </geometry>
          <surface>
            <contact>
              <ode>
                <kp>1e+12</kp>
                <kd>100</kd>
                <min_depth>0.05</min_depth>
              </ode>
            </contact>
            <friction>
              <ode>
                <mu>50</mu>
                <mu2>50</mu2>
              </ode>
              <torsional>
                <ode/>
              </torsional>
            </friction>
            <bounce/>
          </surface>
          <max_contacts>10</max_contacts>
        </collision>
        <visual name='mid_right_link_visual'>
          <pose>0 0 0 0 -0 0</pose>
          <geometry>
            <mesh>
              <scale>1 1 1</scale>
              <uri>file:///home/rhex/mnt/rhex_ws/install/rhex_description/share/rhex_description/meshes/rpk10_leg.dae</uri>
            </mesh>
          </geometry>
        </visual>
        <self_collide>0</self_collide>
        <enable_wind>0</enable_wind>
        <kinematic>0</kinematic>
      </link>
      <joint name='rear_left_joint' type='revolute'>
        <pose relative_to='base_link'>-0.19 0.1235 0 0 -0 0</pose>
        <parent>base_link</parent>
        <child>rear_left_link</child>
        <axis>
          <xyz>0 1 0</xyz>
          <limit>
            <lower>-1e+16</lower>
            <upper>1e+16</upper>
          </limit>
          <dynamics>
            <damping>0.5</damping>
            <friction>0</friction>
            <spring_reference>0</spring_reference>
            <spring_stiffness>0</spring_stiffness>
          </dynamics>
        </axis>
      </joint>
      <link name='rear_left_link'>
        <pose relative_to='rear_left_joint'>0 0 0 0 -0 0</pose>
        <inertial>
          <pose>0 0 -0.08 0 -0 0</pose>
          <mass>0.05</mass>
          <inertia>
            <ixx>0.000130865</ixx>
            <ixy>0</ixy>
            <ixz>0</ixz>
            <iyy>0.000166666</iyy>
            <iyz>0</iyz>
            <izz>4.40694e-05</izz>
          </inertia>
        </inertial>
        <collision name='rear_left_link_collision'>
          <pose>0 0 0 0 -0 0</pose>
          <geometry>
            <mesh>
              <scale>1 1 1</scale>
              <uri>file:///home/rhex/mnt/rhex_ws/install/rhex_description/share/rhex_description/meshes/rpk10_leg.dae</uri>
            </mesh>
          </geometry>
          <surface>
            <contact>
              <ode>
                <kp>1e+12</kp>
                <kd>100</kd>
                <min_depth>0.05</min_depth>
              </ode>
            </contact>
            <friction>
              <ode>
                <mu>50</mu>
                <mu2>50</mu2>
              </ode>
              <torsional>
                <ode/>
              </torsional>
            </friction>
            <bounce/>
          </surface>
          <max_contacts>10</max_contacts>
        </collision>
        <visual name='rear_left_link_visual'>
          <pose>0 0 0 0 -0 0</pose>
          <geometry>
            <mesh>
              <scale>1 1 1</scale>
              <uri>file:///home/rhex/mnt/rhex_ws/install/rhex_description/share/rhex_description/meshes/rpk10_leg.dae</uri>
            </mesh>
          </geometry>
        </visual>
        <self_collide>0</self_collide>
        <enable_wind>0</enable_wind>
        <kinematic>0</kinematic>
      </link>
      <joint name='rear_right_joint' type='revolute'>
        <pose relative_to='base_link'>-0.19 -0.1235 0 0 -0 0</pose>
        <parent>base_link</parent>
        <child>rear_right_link</child>
        <axis>
          <xyz>0 1 0</xyz>
          <limit>
            <lower>-1e+16</lower>
            <upper>1e+16</upper>
          </limit>
          <dynamics>
            <damping>0.5</damping>
            <friction>0</friction>
            <spring_reference>0</spring_reference>
            <spring_stiffness>0</spring_stiffness>
          </dynamics>
        </axis>
      </joint>
      <link name='rear_right_link'>
        <pose relative_to='rear_right_joint'>0 0 0 0 -0 0</pose>
        <inertial>
          <pose>0 0 -0.08 0 -0 0</pose>
          <mass>0.05</mass>
          <inertia>
            <ixx>0.000130865</ixx>
            <ixy>0</ixy>
            <ixz>0</ixz>
            <iyy>0.000166666</iyy>
            <iyz>0</iyz>
            <izz>4.40694e-05</izz>
          </inertia>
        </inertial>
        <collision name='rear_right_link_collision'>
          <pose>0 0 0 0 -0 0</pose>
          <geometry>
            <mesh>
              <scale>1 1 1</scale>
              <uri>file:///home/rhex/mnt/rhex_ws/install/rhex_description/share/rhex_description/meshes/rpk10_leg.dae</uri>
            </mesh>
          </geometry>
          <surface>
            <contact>
              <ode>
                <kp>1e+12</kp>
                <kd>100</kd>
                <min_depth>0.05</min_depth>
              </ode>
            </contact>
            <friction>
              <ode>
                <mu>50</mu>
                <mu2>50</mu2>
              </ode>
              <torsional>
                <ode/>
              </torsional>
            </friction>
            <bounce/>
          </surface>
          <max_contacts>10</max_contacts>
        </collision>
        <visual name='rear_right_link_visual'>
          <pose>0 0 0 0 -0 0</pose>
          <geometry>
            <mesh>
              <scale>1 1 1</scale>
              <uri>file:///home/rhex/mnt/rhex_ws/install/rhex_description/share/rhex_description/meshes/rpk10_leg.dae</uri>
            </mesh>
          </geometry>
        </visual>
        <self_collide>0</self_collide>
        <enable_wind>0</enable_wind>
        <kinematic>0</kinematic>
      </link>
      <plugin name='p3d_base_controller' filename='libgazebo_ros_p3d.so'>
        <ros>
          <argument>/odom:=odom/robot_pos</argument>
        </ros>
        <body_name>base_link</body_name>
        <frame_name>world</frame_name>
        <update_rate>30.0</update_rate>
        <xyz_offset>0 0 0</xyz_offset>
        <rpy_offset>0 0 0</rpy_offset>
        <gaussian_noise>0.01</gaussian_noise>
      </plugin>
      <static>0</static>
      <plugin name='gazebo_ros2_control' filename='libgazebo_ros2_control.so'>
        <parameters>/home/rhex/mnt/rhex_ws/install/rhex_description/share/rhex_description/config/ros_control.yaml</parameters>
      </plugin>
      <pose>0 0 0.1 0 -0 0</pose>
    </model>
    <state world_name='default'>
      <sim_time>1377 175000000</sim_time>
      <real_time>38 608965891</real_time>
      <wall_time>1722932921 596953075</wall_time>
      <iterations>38268</iterations>
      <model name='ambulance'>
        <pose>11.733 3.98539 0 -0.049826 -0.044375 -0.727016</pose>
        <scale>1 1 1</scale>
        <link name='link'>
          <pose>11.733 3.98539 0 -0.049826 -0.044375 -0.727016</pose>
          <velocity>0 0 0 0 -0 0</velocity>
          <acceleration>0 0 0 0 -0 0</acceleration>
          <wrench>0 0 0 0 -0 0</wrench>
        </link>
      </model>
      <model name='ground_plane'>
        <pose>0 0 0 0 -0 0</pose>
        <scale>1 1 1</scale>
        <link name='link'>
          <pose>0 0 0 0 -0 0</pose>
          <velocity>0 0 0 0 -0 0</velocity>
          <acceleration>0 0 0 0 -0 0</acceleration>
          <wrench>0 0 0 0 -0 0</wrench>
        </link>
      </model>
      <model name='person_standing'>
        <pose>2.41485 -4.64001 0 -1e-06 -1e-06 -1.54997</pose>
        <scale>1 1 1</scale>
        <link name='link'>
          <pose>2.41485 -4.64001 0 -1e-06 -1e-06 -1.54997</pose>
          <velocity>0 0 0 0 -0 0</velocity>
          <acceleration>-1.49628 -2.24336 1.55289 -0.89109 -1.45661 3.0971</acceleration>
          <wrench>-119.702 -179.469 124.231 0 -0 0</wrench>
        </link>
      </model>
      <model name='rhex'>
        <pose>-0.126848 1.33451 0.056006 -5e-06 -2.1e-05 -1.13672</pose>
        <scale>1 1 1</scale>
        <link name='base_link'>
          <pose>-0.126848 1.33451 0.056006 -5e-06 -2.1e-05 -1.13672</pose>
          <velocity>-0.000558 0.001177 -0.005723 -0.021624 -0.004615 0.00115</velocity>
          <acceleration>-0.094432 0.239233 -8.8972 -0.602671 -1.27788 1.09713</acceleration>
          <wrench>-1.19419 3.02535 -112.514 0 -0 0</wrench>
        </link>
        <link name='front_left_link'>
          <pose>0.065105 1.21408 0.056019 3.14157 -1.2799 2.00488</pose>
          <velocity>-0.0009 0.00138 -0.001887 -0.027753 -0.009151 0.005882</velocity>
          <acceleration>-2.80199 6.45932 9.43033 0.283117 1.33461 -3.1154</acceleration>
          <wrench>-0.140099 0.322966 0.471516 0 -0 0</wrench>
        </link>
        <link name='front_right_link'>
          <pose>-0.158987 1.1102 0.056018 3.14152 -1.27978 2.00492</pose>
          <velocity>-0.000234 0.000887 -0.001383 -0.017574 -0.002911 0.001842</velocity>
          <acceleration>-1.53933 3.85598 0.126154 2.57006 -0.278075 2.91527</acceleration>
          <wrench>-0.076967 0.192799 0.006308 0 -0 0</wrench>
        </link>
        <link name='mid_left_link'>
          <pose>0.020124 1.40265 0.056012 -3.14146 -1.2797 2.00474</pose>
          <velocity>-0.001297 0.002945 -0.004026 -0.052917 -0.023215 0.000169</velocity>
          <acceleration>-2.27527 5.00226 0.5862 -2.2797 -0.548359 0.976798</acceleration>
          <wrench>-0.113764 0.250113 0.02931 0 -0 0</wrench>
        </link>
        <link name='mid_right_link'>
          <pose>-0.273828 1.26639 0.056018 3.14159 -1.27987 2.00487</pose>
          <velocity>-0.001228 0.00223 -0.002998 -0.041675 -0.0184 0.003154</velocity>
          <acceleration>-2.92937 6.06156 8.50302 2.98789 -1.34842 -0.872181</acceleration>
          <wrench>-0.146469 0.303078 0.425151 0 -0 0</wrench>
        </link>
        <link name='rear_left_link'>
          <pose>-0.094714 1.55884 0.056009 -3.1415 -1.27966 2.0048</pose>
          <velocity>-0.003003 0.003639 -0.006727 -0.084598 -0.042209 0.016351</velocity>
          <acceleration>-2.38887 5.08983 0.60218 -1.69494 -0.838242 2.88151</acceleration>
          <wrench>-0.119444 0.254492 0.030109 0 -0 0</wrench>
        </link>
        <link name='rear_right_link'>
          <pose>-0.318806 1.45495 0.056009 -3.1415 -1.27966 2.00479</pose>
          <velocity>-0.002788 0.003031 -0.005843 -0.073453 -0.036987 0.016944</velocity>
          <acceleration>-2.0353 4.33411 0.538092 1.23536 0.347372 -1.98056</acceleration>
          <wrench>-0.101765 0.216706 0.026905 0 -0 0</wrench>
        </link>
      </model>
      <light name='sun'>
        <pose>0 0 10 0 -0 0</pose>
      </light>
    </state>
    <gui fullscreen='0'>
      <camera name='user_camera'>
        <pose>-15.6455 -7.36926 13.9352 0 0.584453 0.089665</pose>
        <view_controller>orbit</view_controller>
        <projection_type>perspective</projection_type>
      </camera>
    </gui>
    <model name='rhex'>
      <link name='base_link'>
        <inertial>
          <pose>0.000443 8e-06 0.00189 0 -0 0</pose>
          <mass>12.646</mass>
          <inertia>
            <ixx>0.0587881</ixx>
            <ixy>-2.79884e-05</ixy>
            <ixz>-0.000629803</ixz>
            <iyy>0.338307</iyy>
            <iyz>-1.20641e-05</iyz>
            <izz>0.36304</izz>
          </inertia>
        </inertial>
        <collision name='base_link_collision'>
          <pose>0 0 0 0 -0 0</pose>
          <geometry>
            <mesh>
              <scale>1 1 1</scale>
              <uri>file:///home/rhex/mnt/rhex_ws/install/rhex_description/share/rhex_description/meshes/rpk10_chassis.dae</uri>
            </mesh>
          </geometry>
          <surface>
            <contact>
              <ode/>
            </contact>
            <friction>
              <ode/>
              <torsional>
                <ode/>
              </torsional>
            </friction>
            <bounce/>
          </surface>
          <max_contacts>10</max_contacts>
        </collision>
        <collision name='base_link_fixed_joint_lump__upper_case_link_collision_1'>
          <pose>0 0 0.055 0 -0 0</pose>
          <geometry>
            <mesh>
              <scale>0.001 0.001 0.001</scale>
              <uri>file:///home/rhex/mnt/rhex_ws/install/rhex_description/share/rhex_description/meshes/upper_case.dae</uri>
            </mesh>
          </geometry>
          <max_contacts>10</max_contacts>
          <surface>
            <contact>
              <ode/>
            </contact>
            <bounce/>
            <friction>
              <torsional>
                <ode/>
              </torsional>
              <ode/>
            </friction>
          </surface>
        </collision>
        <collision name='base_link_fixed_joint_lump__camera_link_collision_2'>
          <pose>0.267 0.0055 0.1155 0 -0 0</pose>
          <geometry>
            <box>
              <size>0.015 0.0867 0.022</size>
            </box>
          </geometry>
          <surface>
            <contact>
              <ode/>
            </contact>
            <friction>
              <ode/>
              <torsional>
                <ode/>
              </torsional>
            </friction>
            <bounce/>
          </surface>
          <max_contacts>10</max_contacts>
        </collision>
        <collision name='base_link_fixed_joint_lump__imu_link_collision_3'>
          <pose>0.267 -0.005 0.0885 0 -0 0</pose>
          <geometry>
            <box>
              <size>0.015 0.115 0.02</size>
            </box>
          </geometry>
          <surface>
            <contact>
              <ode/>
            </contact>
            <friction>
              <ode/>
              <torsional>
                <ode/>
              </torsional>
            </friction>
            <bounce/>
          </surface>
          <max_contacts>10</max_contacts>
        </collision>
        <collision name='base_link_fixed_joint_lump__lidar_link_collision_4'>
          <pose>0 0 0.172 0 -0 0</pose>
          <geometry>
            <cylinder>
              <length>0.056</length>
              <radius>0.0508</radius>
            </cylinder>
          </geometry>
          <surface>
            <contact>
              <ode/>
            </contact>
            <friction>
              <ode/>
              <torsional>
                <ode/>
              </torsional>
            </friction>
            <bounce/>
          </surface>
          <max_contacts>10</max_contacts>
        </collision>
        <visual name='base_link_visual'>
          <pose>0 0 0 0 -0 0</pose>
          <geometry>
            <mesh>
              <scale>1 1 1</scale>
              <uri>file:///home/rhex/mnt/rhex_ws/install/rhex_description/share/rhex_description/meshes/rpk10_chassis.dae</uri>
            </mesh>
          </geometry>
          <material>
            <script>
              <name>Gazebo/Red</name>
              <uri>file://media/materials/scripts/gazebo.material</uri>
            </script>
          </material>
        </visual>
        <visual name='base_link_fixed_joint_lump__upper_case_link_visual_1'>
          <pose>0 0 0.055 0 -0 0</pose>
          <geometry>
            <mesh>
              <scale>0.001 0.001 0.001</scale>
              <uri>file:///home/rhex/mnt/rhex_ws/install/rhex_description/share/rhex_description/meshes/upper_case.dae</uri>
            </mesh>
          </geometry>
        </visual>
        <visual name='base_link_fixed_joint_lump__camera_link_visual_2'>
          <pose>0.267 0.0055 0.1155 0 -0 0</pose>
          <geometry>
            <box>
              <size>0.015 0.0867 0.022</size>
            </box>
          </geometry>
        </visual>
        <visual name='base_link_fixed_joint_lump__imu_link_visual_3'>
          <pose>0.267 -0.005 0.0885 0 -0 0</pose>
          <geometry>
            <box>
              <size>0.015 0.115 0.02</size>
            </box>
          </geometry>
        </visual>
        <visual name='base_link_fixed_joint_lump__lidar_link_visual_4'>
          <pose>0 0 0.172 0 -0 0</pose>
          <geometry>
            <cylinder>
              <length>0.056</length>
              <radius>0.0508</radius>
            </cylinder>
          </geometry>
        </visual>
        <sensor name='depth_camera' type='depth'>
          <visualize>1</visualize>
          <update_rate>30</update_rate>
          <camera name='camera'>
            <horizontal_fov>1.0472</horizontal_fov>
            <image>
              <width>640</width>
              <height>480</height>
              <format>B8G8R8</format>
            </image>
            <clip>
              <near>0.05</near>
              <far>30</far>
            </clip>
            <noise>
              <type>gaussian</type>
              <mean>0</mean>
              <stddev>0.007</stddev>
            </noise>
          </camera>
          <plugin name='depth_camera_controller' filename='libgazebo_ros_camera.so'>
            <update_rate>0.0</update_rate>
            <frame_name>camera_depth_frame</frame_name>
            <min_depth>0.2</min_depth>
            <max_depth>4.0</max_depth>
          </plugin>
          <pose>0.267 0.0055 0.1155 0 -0 0</pose>
        </sensor>
        <sensor name='imu_sensor' type='imu'>
          <plugin name='imu_plugin' filename='libgazebo_ros_imu_sensor.so'>
            <ros>
              <namespace>/imu</namespace>
              <remapping>~/out:=data</remapping>
            </ros>
            <initial_orientation_as_reference>0</initial_orientation_as_reference>
          </plugin>
          <always_on>1</always_on>
          <update_rate>1000</update_rate>
          <visualize>1</visualize>
          <imu>
            <angular_velocity>
              <x>
                <noise type='gaussian'>
                  <mean>0</mean>
                  <stddev>0.0002</stddev>
                  <bias_mean>7.5e-06</bias_mean>
                  <bias_stddev>8e-07</bias_stddev>
                </noise>
              </x>
              <y>
                <noise type='gaussian'>
                  <mean>0</mean>
                  <stddev>0.0002</stddev>
                  <bias_mean>7.5e-06</bias_mean>
                  <bias_stddev>8e-07</bias_stddev>
                </noise>
              </y>
              <z>
                <noise type='gaussian'>
                  <mean>0</mean>
                  <stddev>0.0002</stddev>
                  <bias_mean>7.5e-06</bias_mean>
                  <bias_stddev>8e-07</bias_stddev>
                </noise>
              </z>
            </angular_velocity>
            <linear_acceleration>
              <x>
                <noise type='gaussian'>
                  <mean>0</mean>
                  <stddev>0.017</stddev>
                  <bias_mean>0.1</bias_mean>
                  <bias_stddev>0.001</bias_stddev>
                </noise>
              </x>
              <y>
                <noise type='gaussian'>
                  <mean>0</mean>
                  <stddev>0.017</stddev>
                  <bias_mean>0.1</bias_mean>
                  <bias_stddev>0.001</bias_stddev>
                </noise>
              </y>
              <z>
                <noise type='gaussian'>
                  <mean>0</mean>
                  <stddev>0.017</stddev>
                  <bias_mean>0.1</bias_mean>
                  <bias_stddev>0.001</bias_stddev>
                </noise>
              </z>
            </linear_acceleration>
          </imu>
          <pose>0.267 -0.005 0.0885 0 -0 0</pose>
        </sensor>
        <sensor name='lidar' type='ray'>
          <always_on>1</always_on>
          <visualize>0</visualize>
          <update_rate>5</update_rate>
          <ray>
            <scan>
              <horizontal>
                <samples>360</samples>
                <resolution>1</resolution>
                <min_angle>0</min_angle>
                <max_angle>6.28</max_angle>
              </horizontal>
              <vertical>
                <samples>1</samples>
                <min_angle>0</min_angle>
                <max_angle>0</max_angle>
              </vertical>
            </scan>
            <range>
              <min>0.12</min>
              <max>3.5</max>
              <resolution>0.015</resolution>
            </range>
            <noise>
              <type>gaussian</type>
              <mean>0</mean>
              <stddev>0.01</stddev>
            </noise>
          </ray>
          <plugin name='scan' filename='libgazebo_ros_ray_sensor.so'>
            <ros>
              <remapping>~/out:=scan</remapping>
            </ros>
            <output_type>sensor_msgs/LaserScan</output_type>
            <frame_name>lidar_link</frame_name>
          </plugin>
          <pose>0 0 0.172 0 -0 0</pose>
        </sensor>
        <self_collide>0</self_collide>
        <enable_wind>0</enable_wind>
        <kinematic>0</kinematic>
      </link>
      <joint name='front_left_joint' type='revolute'>
        <pose relative_to='base_link'>0.19 0.1235 0 0 -0 0</pose>
        <parent>base_link</parent>
        <child>front_left_link</child>
        <axis>
          <xyz>0 1 0</xyz>
          <limit>
            <lower>-1e+16</lower>
            <upper>1e+16</upper>
          </limit>
          <dynamics>
            <damping>0.5</damping>
            <friction>0</friction>
            <spring_reference>0</spring_reference>
            <spring_stiffness>0</spring_stiffness>
          </dynamics>
        </axis>
      </joint>
      <link name='front_left_link'>
        <pose relative_to='front_left_joint'>0 0 0 0 -0 0</pose>
        <inertial>
          <pose>0 0 -0.08 0 -0 0</pose>
          <mass>0.05</mass>
          <inertia>
            <ixx>0.000130865</ixx>
            <ixy>0</ixy>
            <ixz>0</ixz>
            <iyy>0.000166666</iyy>
            <iyz>0</iyz>
            <izz>4.40694e-05</izz>
          </inertia>
        </inertial>
        <collision name='front_left_link_collision'>
          <pose>0 0 0 0 -0 0</pose>
          <geometry>
            <mesh>
              <scale>1 1 1</scale>
              <uri>file:///home/rhex/mnt/rhex_ws/install/rhex_description/share/rhex_description/meshes/rpk10_leg.dae</uri>
            </mesh>
          </geometry>
          <surface>
            <contact>
              <ode>
                <kp>1e+12</kp>
                <kd>100</kd>
                <min_depth>0.05</min_depth>
              </ode>
            </contact>
            <friction>
              <ode>
                <mu>50</mu>
                <mu2>50</mu2>
              </ode>
              <torsional>
                <ode/>
              </torsional>
            </friction>
            <bounce/>
          </surface>
          <max_contacts>10</max_contacts>
        </collision>
        <visual name='front_left_link_visual'>
          <pose>0 0 0 0 -0 0</pose>
          <geometry>
            <mesh>
              <scale>1 1 1</scale>
              <uri>file:///home/rhex/mnt/rhex_ws/install/rhex_description/share/rhex_description/meshes/rpk10_leg.dae</uri>
            </mesh>
          </geometry>
        </visual>
        <self_collide>0</self_collide>
        <enable_wind>0</enable_wind>
        <kinematic>0</kinematic>
      </link>
      <joint name='front_right_joint' type='revolute'>
        <pose relative_to='base_link'>0.19 -0.1235 0 0 -0 0</pose>
        <parent>base_link</parent>
        <child>front_right_link</child>
        <axis>
          <xyz>0 1 0</xyz>
          <limit>
            <lower>-1e+16</lower>
            <upper>1e+16</upper>
          </limit>
          <dynamics>
            <damping>0.5</damping>
            <friction>0</friction>
            <spring_reference>0</spring_reference>
            <spring_stiffness>0</spring_stiffness>
          </dynamics>
        </axis>
      </joint>
      <link name='front_right_link'>
        <pose relative_to='front_right_joint'>0 0 0 0 -0 0</pose>
        <inertial>
          <pose>0 0 -0.08 0 -0 0</pose>
          <mass>0.05</mass>
          <inertia>
            <ixx>0.000130865</ixx>
            <ixy>0</ixy>
            <ixz>0</ixz>
            <iyy>0.000166666</iyy>
            <iyz>0</iyz>
            <izz>4.40694e-05</izz>
          </inertia>
        </inertial>
        <collision name='front_right_link_collision'>
          <pose>0 0 0 0 -0 0</pose>
          <geometry>
            <mesh>
              <scale>1 1 1</scale>
              <uri>file:///home/rhex/mnt/rhex_ws/install/rhex_description/share/rhex_description/meshes/rpk10_leg.dae</uri>
            </mesh>
          </geometry>
          <surface>
            <contact>
              <ode>
                <kp>1e+12</kp>
                <kd>100</kd>
                <min_depth>0.05</min_depth>
              </ode>
            </contact>
            <friction>
              <ode>
                <mu>50</mu>
                <mu2>50</mu2>
              </ode>
              <torsional>
                <ode/>
              </torsional>
            </friction>
            <bounce/>
          </surface>
          <max_contacts>10</max_contacts>
        </collision>
        <visual name='front_right_link_visual'>
          <pose>0 0 0 0 -0 0</pose>
          <geometry>
            <mesh>
              <scale>1 1 1</scale>
              <uri>file:///home/rhex/mnt/rhex_ws/install/rhex_description/share/rhex_description/meshes/rpk10_leg.dae</uri>
            </mesh>
          </geometry>
        </visual>
        <self_collide>0</self_collide>
        <enable_wind>0</enable_wind>
        <kinematic>0</kinematic>
      </link>
      <joint name='mid_left_joint' type='revolute'>
        <pose relative_to='base_link'>0 0.162 0 0 -0 0</pose>
        <parent>base_link</parent>
        <child>mid_left_link</child>
        <axis>
          <xyz>0 1 0</xyz>
          <limit>
            <lower>-1e+16</lower>
            <upper>1e+16</upper>
          </limit>
          <dynamics>
            <damping>0.5</damping>
            <friction>0</friction>
            <spring_reference>0</spring_reference>
            <spring_stiffness>0</spring_stiffness>
          </dynamics>
        </axis>
      </joint>
      <link name='mid_left_link'>
        <pose relative_to='mid_left_joint'>0 0 0 0 -0 0</pose>
        <inertial>
          <pose>0 0 -0.08 0 -0 0</pose>
          <mass>0.05</mass>
          <inertia>
            <ixx>0.000130865</ixx>
            <ixy>0</ixy>
            <ixz>0</ixz>
            <iyy>0.000166666</iyy>
            <iyz>0</iyz>
            <izz>4.40694e-05</izz>
          </inertia>
        </inertial>
        <collision name='mid_left_link_collision'>
          <pose>0 0 0 0 -0 0</pose>
          <geometry>
            <mesh>
              <scale>1 1 1</scale>
              <uri>file:///home/rhex/mnt/rhex_ws/install/rhex_description/share/rhex_description/meshes/rpk10_leg.dae</uri>
            </mesh>
          </geometry>
          <surface>
            <contact>
              <ode>
                <kp>1e+12</kp>
                <kd>100</kd>
                <min_depth>0.05</min_depth>
              </ode>
            </contact>
            <friction>
              <ode>
                <mu>50</mu>
                <mu2>50</mu2>
              </ode>
              <torsional>
                <ode/>
              </torsional>
            </friction>
            <bounce/>
          </surface>
          <max_contacts>10</max_contacts>
        </collision>
        <visual name='mid_left_link_visual'>
          <pose>0 0 0 0 -0 0</pose>
          <geometry>
            <mesh>
              <scale>1 1 1</scale>
              <uri>file:///home/rhex/mnt/rhex_ws/install/rhex_description/share/rhex_description/meshes/rpk10_leg.dae</uri>
            </mesh>
          </geometry>
        </visual>
        <self_collide>0</self_collide>
        <enable_wind>0</enable_wind>
        <kinematic>0</kinematic>
      </link>
      <joint name='mid_right_joint' type='revolute'>
        <pose relative_to='base_link'>0 -0.162 0 0 -0 0</pose>
        <parent>base_link</parent>
        <child>mid_right_link</child>
        <axis>
          <xyz>0 1 0</xyz>
          <limit>
            <lower>-1e+16</lower>
            <upper>1e+16</upper>
          </limit>
          <dynamics>
            <damping>0.5</damping>
            <friction>0</friction>
            <spring_reference>0</spring_reference>
            <spring_stiffness>0</spring_stiffness>
          </dynamics>
        </axis>
      </joint>
      <link name='mid_right_link'>
        <pose relative_to='mid_right_joint'>0 0 0 0 -0 0</pose>
        <inertial>
          <pose>0 0 -0.08 0 -0 0</pose>
          <mass>0.05</mass>
          <inertia>
            <ixx>0.000130865</ixx>
            <ixy>0</ixy>
            <ixz>0</ixz>
            <iyy>0.000166666</iyy>
            <iyz>0</iyz>
            <izz>4.40694e-05</izz>
          </inertia>
        </inertial>
        <collision name='mid_right_link_collision'>
          <pose>0 0 0 0 -0 0</pose>
          <geometry>
            <mesh>
              <scale>1 1 1</scale>
              <uri>file:///home/rhex/mnt/rhex_ws/install/rhex_description/share/rhex_description/meshes/rpk10_leg.dae</uri>
            </mesh>
          </geometry>
          <surface>
            <contact>
              <ode>
                <kp>1e+12</kp>
                <kd>100</kd>
                <min_depth>0.05</min_depth>
              </ode>
            </contact>
            <friction>
              <ode>
                <mu>50</mu>
                <mu2>50</mu2>
              </ode>
              <torsional>
                <ode/>
              </torsional>
            </friction>
            <bounce/>
          </surface>
          <max_contacts>10</max_contacts>
        </collision>
        <visual name='mid_right_link_visual'>
          <pose>0 0 0 0 -0 0</pose>
          <geometry>
            <mesh>
              <scale>1 1 1</scale>
              <uri>file:///home/rhex/mnt/rhex_ws/install/rhex_description/share/rhex_description/meshes/rpk10_leg.dae</uri>
            </mesh>
          </geometry>
        </visual>
        <self_collide>0</self_collide>
        <enable_wind>0</enable_wind>
        <kinematic>0</kinematic>
      </link>
      <joint name='rear_left_joint' type='revolute'>
        <pose relative_to='base_link'>-0.19 0.1235 0 0 -0 0</pose>
        <parent>base_link</parent>
        <child>rear_left_link</child>
        <axis>
          <xyz>0 1 0</xyz>
          <limit>
            <lower>-1e+16</lower>
            <upper>1e+16</upper>
          </limit>
          <dynamics>
            <damping>0.5</damping>
            <friction>0</friction>
            <spring_reference>0</spring_reference>
            <spring_stiffness>0</spring_stiffness>
          </dynamics>
        </axis>
      </joint>
      <link name='rear_left_link'>
        <pose relative_to='rear_left_joint'>0 0 0 0 -0 0</pose>
        <inertial>
          <pose>0 0 -0.08 0 -0 0</pose>
          <mass>0.05</mass>
          <inertia>
            <ixx>0.000130865</ixx>
            <ixy>0</ixy>
            <ixz>0</ixz>
            <iyy>0.000166666</iyy>
            <iyz>0</iyz>
            <izz>4.40694e-05</izz>
          </inertia>
        </inertial>
        <collision name='rear_left_link_collision'>
          <pose>0 0 0 0 -0 0</pose>
          <geometry>
            <mesh>
              <scale>1 1 1</scale>
              <uri>file:///home/rhex/mnt/rhex_ws/install/rhex_description/share/rhex_description/meshes/rpk10_leg.dae</uri>
            </mesh>
          </geometry>
          <surface>
            <contact>
              <ode>
                <kp>1e+12</kp>
                <kd>100</kd>
                <min_depth>0.05</min_depth>
              </ode>
            </contact>
            <friction>
              <ode>
                <mu>50</mu>
                <mu2>50</mu2>
              </ode>
              <torsional>
                <ode/>
              </torsional>
            </friction>
            <bounce/>
          </surface>
          <max_contacts>10</max_contacts>
        </collision>
        <visual name='rear_left_link_visual'>
          <pose>0 0 0 0 -0 0</pose>
          <geometry>
            <mesh>
              <scale>1 1 1</scale>
              <uri>file:///home/rhex/mnt/rhex_ws/install/rhex_description/share/rhex_description/meshes/rpk10_leg.dae</uri>
            </mesh>
          </geometry>
        </visual>
        <self_collide>0</self_collide>
        <enable_wind>0</enable_wind>
        <kinematic>0</kinematic>
      </link>
      <joint name='rear_right_joint' type='revolute'>
        <pose relative_to='base_link'>-0.19 -0.1235 0 0 -0 0</pose>
        <parent>base_link</parent>
        <child>rear_right_link</child>
        <axis>
          <xyz>0 1 0</xyz>
          <limit>
            <lower>-1e+16</lower>
            <upper>1e+16</upper>
          </limit>
          <dynamics>
            <damping>0.5</damping>
            <friction>0</friction>
            <spring_reference>0</spring_reference>
            <spring_stiffness>0</spring_stiffness>
          </dynamics>
        </axis>
      </joint>
      <link name='rear_right_link'>
        <pose relative_to='rear_right_joint'>0 0 0 0 -0 0</pose>
        <inertial>
          <pose>0 0 -0.08 0 -0 0</pose>
          <mass>0.05</mass>
          <inertia>
            <ixx>0.000130865</ixx>
            <ixy>0</ixy>
            <ixz>0</ixz>
            <iyy>0.000166666</iyy>
            <iyz>0</iyz>
            <izz>4.40694e-05</izz>
          </inertia>
        </inertial>
        <collision name='rear_right_link_collision'>
          <pose>0 0 0 0 -0 0</pose>
          <geometry>
            <mesh>
              <scale>1 1 1</scale>
              <uri>file:///home/rhex/mnt/rhex_ws/install/rhex_description/share/rhex_description/meshes/rpk10_leg.dae</uri>
            </mesh>
          </geometry>
          <surface>
            <contact>
              <ode>
                <kp>1e+12</kp>
                <kd>100</kd>
                <min_depth>0.05</min_depth>
              </ode>
            </contact>
            <friction>
              <ode>
                <mu>50</mu>
                <mu2>50</mu2>
              </ode>
              <torsional>
                <ode/>
              </torsional>
            </friction>
            <bounce/>
          </surface>
          <max_contacts>10</max_contacts>
        </collision>
        <visual name='rear_right_link_visual'>
          <pose>0 0 0 0 -0 0</pose>
          <geometry>
            <mesh>
              <scale>1 1 1</scale>
              <uri>file:///home/rhex/mnt/rhex_ws/install/rhex_description/share/rhex_description/meshes/rpk10_leg.dae</uri>
            </mesh>
          </geometry>
        </visual>
        <self_collide>0</self_collide>
        <enable_wind>0</enable_wind>
        <kinematic>0</kinematic>
      </link>
      <plugin name='p3d_base_controller' filename='libgazebo_ros_p3d.so'>
        <ros>
          <argument>/odom:=odom/robot_pos</argument>
        </ros>
        <body_name>base_link</body_name>
        <frame_name>world</frame_name>
        <update_rate>30.0</update_rate>
        <xyz_offset>0 0 0</xyz_offset>
        <rpy_offset>0 0 0</rpy_offset>
        <gaussian_noise>0.01</gaussian_noise>
      </plugin>
      <static>0</static>
      <plugin name='gazebo_ros2_control' filename='libgazebo_ros2_control.so'>
        <parameters>/home/rhex/mnt/rhex_ws/install/rhex_description/share/rhex_description/config/ros_control.yaml</parameters>
      </plugin>
      <pose>0 0 0.1 0 -0 0</pose>
    </model>
    <model name='person_standing'>
      <link name='link'>
        <inertial>
          <pose>0 -0.1 0.95 0 -0 0</pose>
          <mass>80</mass>
          <inertia>
            <ixx>24.88</ixx>
            <ixy>0</ixy>
            <ixz>0</ixz>
            <iyy>25.73</iyy>
            <iyz>0</iyz>
            <izz>2.48</izz>
          </inertia>
        </inertial>
        <collision name='bottom'>
          <pose>0 -0.1 0.01 0 -0 0</pose>
          <geometry>
            <box>
              <size>0.5 0.35 0.02</size>
            </box>
          </geometry>
          <max_contacts>10</max_contacts>
          <surface>
            <contact>
              <ode/>
            </contact>
            <bounce/>
            <friction>
              <torsional>
                <ode/>
              </torsional>
              <ode/>
            </friction>
          </surface>
        </collision>
        <collision name='person'>
          <pose>0 0 0.02 0.04 -0 0</pose>
          <geometry>
            <mesh>
              <uri>model://person_standing/meshes/standing.dae</uri>
            </mesh>
          </geometry>
          <max_contacts>10</max_contacts>
          <surface>
            <contact>
              <ode/>
            </contact>
            <bounce/>
            <friction>
              <torsional>
                <ode/>
              </torsional>
              <ode/>
            </friction>
          </surface>
        </collision>
        <visual name='visual'>
          <pose>0 0 0.02 0.04 -0 0</pose>
          <geometry>
            <mesh>
              <uri>model://person_standing/meshes/standing.dae</uri>
            </mesh>
          </geometry>
        </visual>
        <self_collide>0</self_collide>
        <enable_wind>0</enable_wind>
        <kinematic>0</kinematic>
      </link>
      <pose>8.51211 1.53405 0 0 -0 0</pose>
    </model>
    <model name='ambulance'>
      <static>1</static>
      <link name='link'>
        <collision name='collision'>
          <geometry>
            <mesh>
              <scale>0.0254 0.0254 0.0254</scale>
              <uri>model://ambulance/meshes/ambulance.obj</uri>
            </mesh>
          </geometry>
          <max_contacts>10</max_contacts>
          <surface>
            <contact>
              <ode/>
            </contact>
            <bounce/>
            <friction>
              <torsional>
                <ode/>
              </torsional>
              <ode/>
            </friction>
          </surface>
        </collision>
        <visual name='visual'>
          <geometry>
            <mesh>
              <scale>0.0254 0.0254 0.0254</scale>
              <uri>model://ambulance/meshes/ambulance.obj</uri>
            </mesh>
          </geometry>
        </visual>
        <self_collide>0</self_collide>
        <enable_wind>0</enable_wind>
        <kinematic>0</kinematic>
      </link>
      <pose>6.83653 3.98539 0 0 -0 0</pose>
    </model>
  </world>
</sdf>
